Workbook

Sheet Steel Based Product
B2: No | C2: Kegiatan | D2: Unit | F2: 45658 | G2: 45689 | H2: 45717 | I2: 45748 | J2: 45778 | K2: 45809 | L2: 45839 | M2: 45870 | N2: 45901 | O2: 45931 | P2: 45962 | Q2: 45992
B3: 1 | C3: Tonase Bulanan Steel Based Product | D3: Ton | E3: Target | F3: ='Target Hilirisasi 2025'!E14 -> 2978 | G3: ='Target Hilirisasi 2025'!F14 -> 3255 | H3: ='Target Hilirisasi 2025'!G14 -> 2055 | I3: ='Target Hilirisasi 2025'!H14 -> 2030 | J3: ='Target Hilirisasi 2025'!I14 -> 2578 | K3: ='Target Hilirisasi 2025'!J14 -> 3480 | L3: ='Target Hilirisasi 2025'!K14 -> 3605 | M3: ='Target Hilirisasi 2025'!L14 -> 3630 | ... Q3: ='Target Hilirisasi 2025'!P14 -> 2303 | S3: =SUM(F3:Q3) -> 36804
D4: Ton | E4: Realisasi | F4: ='Realisasi Hilirisasi'!S24 -> 551.86479 | G4: ='Realisasi Hilirisasi'!T24 -> 2423.0519 | H4: ='Realisasi Hilirisasi'!U24 -> 1414.3837 | I4: =I59 -> 476.06405 | J4: =J59 -> 2488.66 | K4: =K59 -> 1037.1636 | L4: =L59 -> 1141.9422 | M4: =M59 -> 2246.0612 | N4: =N59 -> 1267.8544 | O4: =O59 -> 4514.828 | P4: =P59 -> 3348.7244 | Q4: =Q59 -> 4492.2404 | S4: =SUM(F4:Q4) -> 25402.839 | U4: =S4/S3 -> 0.69021951
C6: Akumulasi | D6: Ton | E6: Target | F6: =F3 -> 2978 | G6: =F6+G3 -> 6233 | H6: =G6+H3 -> 8288 | I6: =H6+I3 -> 10318 | J6: =I6+J3 -> 12896 | K6: =J6+K3 -> 16376 | L6: =K6+L3 -> 19981 | M6: =L6+M3 -> 23611 | N6: =M6+N3 -> 27241 | ... Q6: =P6+Q3 -> 36804 | S6: =25250 -> 25250 | T6: =Q6-S6 -> 11554
D7: Ton | E7: Realisasi | F7: =F4 -> 551.86479 | G7: =F7+G4 -> 2974.9167 | H7: =G7+H4 -> 4389.3004 | I7: =H7+I4 -> 4865.3645 | J7: =I7+J4 -> 7354.0245 | K7: =J7+K4 -> 8391.1881 | L7: =K7+L4 -> 9533.1302 | M7: =L7+M4 -> 11779.191 | N7: =M7+N4 -> 13047.046 | ... Q7: =P7+Q4 -> 25402.839
D8: % | E8: Capaian | F8: =F7/F6*100 -> 18.53139 | G8: =G7/G6*100 -> 47.728488 | H8: =H7/H6*100 -> 52.959706 | I8: =I7/I6*100 -> 47.154143 | J8: =J7/J6*100 -> 57.025624 | K8: =K7/K6*100 -> 51.240767 | L8: =L7/L6*100 -> 47.710977 | M8: =M7/M6*100 -> 49.888575 | ... Q8: =Q7/Q6*100 -> 69.021951
X13: Ton
W14: Realisasi s/d juni | X14: =K7 -> 8391.1881
W15: tiang listrik KBK+KPI | X15: 6000
W16: rumah ciajur | X16: =Y16*0.8 -> 1000 | Y16: =1250 -> 1250
W17: layton | X17: =900 -> 900
W18: ajp | X18: =100+200 -> 300
W19: wgf | X19: 360
W20: solusi kontruksi | X20: 200
W21: kni Juli sd Des | X21: =600*6 -> 3600
W22: kpdp Juli sd Des | X22: =100*6 -> 600
W23: Lain-Lain | X23: 3000
W25: Total | X25: =SUM(X14:X24) -> 24351.188
X30: =X20+X17+X18+X19+X16 -> 2760
X35: =6/9 -> 0.66666667
F45: =F2 -> 45658 | G45: =G2 -> 45689 | H45: =H2 -> 45717 | I45: =I2 -> 45748 | J45: =J2 -> 45778 | K45: =K2 -> 45809 | L45: =L2 -> 45839 | M45: =M2 -> 45870 | ... Q45: =Q2 -> 45992 | R45: TOTAL
C46: Realisasi
C47: KBK | F47: ='Realisasi Hilirisasi'!S28 -> 143.32434 | G47: ='Realisasi Hilirisasi'!T28 -> 782.00073 | H47: ='Realisasi Hilirisasi'!U28 -> 681.34313 | I47: ='Realisasi Hilirisasi'!V28 -> 208.7867 | J47: ='Realisasi Hilirisasi'!W28 -> 592.8619 | K47: ='Realisasi Hilirisasi'!X28 -> -74.014673 | L47: ='Realisasi Hilirisasi'!Y28 -> 406.85827 | M47: ='Realisasi Hilirisasi'!Z28 -> 245.88916 | ... Q47: ='Realisasi Hilirisasi'!AD28 -> 251.4456 | R47: =SUM(F47:Q47) -> 5428.2944 | S47: =6963+2000+100+25+5000+2500 -> 16588
C48: KPI | F48: ='Realisasi Hilirisasi'!S29 -> 64 | G48: ='Realisasi Hilirisasi'!T29 -> 1293 | H48: ='Realisasi Hilirisasi'!U29 -> 366 | I48: ='Realisasi Hilirisasi'!V29 -> 80.334 | J48: ='Realisasi Hilirisasi'!W29 -> 1638.899 | K48: ='Realisasi Hilirisasi'!X29 -> 864.274 | L48: ='Realisasi Hilirisasi'!Y29 -> 300 | M48: ='Realisasi Hilirisasi'!Z29 -> 1340.533 | ... Q48: ='Realisasi Hilirisasi'!AD29 -> 3953.021 | R48: =SUM(F48:Q48) -> 14083.94 | S48: =3000+SUM(F48:J48) -> 6442.233 | U48: =SUM(F48:K48)/6 -> 717.75117
C49: KNI | F49: ='Realisasi Hilirisasi'!S30 -> 344.54045 | G49: ='Realisasi Hilirisasi'!T30 -> 348.05116 | H49: ='Realisasi Hilirisasi'!U30 -> 367.04059 | I49: ='Realisasi Hilirisasi'!V30 -> 186.94335 | J49: ='Realisasi Hilirisasi'!W30 -> 256.8991 | K49: ='Realisasi Hilirisasi'!X30 -> 246.90429 | L49: ='Realisasi Hilirisasi'!Y30 -> 435.0839 | M49: ='Realisasi Hilirisasi'!Z30 -> 659.639 | ... Q49: ='Realisasi Hilirisasi'!AD30 -> 287.77385 | R49: =SUM(F49:Q49) -> 5890.6043 | S49: =R49/5*7+SUM(F49:J49) -> 9750.3207 | T49: =R49/6 -> 981.76738 | U49: =SUM(F49:K49)/6 -> 291.72982
C50: KPdP | F50: ='Realisasi Hilirisasi'!S31 -> 0 | G50: ='Realisasi Hilirisasi'!T31 -> 0 | H50: ='Realisasi Hilirisasi'!U31 -> 0 | I50: ='Realisasi Hilirisasi'!V31 -> 0 | J50: ='Realisasi Hilirisasi'!W31 -> 0 | K50: ='Realisasi Hilirisasi'!X31 -> 0 | L50: ='Realisasi Hilirisasi'!Y31 -> 0 | M50: ='Realisasi Hilirisasi'!Z31 -> 0 | ... Q50: ='Realisasi Hilirisasi'!AD31 -> 0 | R50: =SUM(F50:Q50) -> 0 | S50: =R50 -> 0 | U50: =SUM(F50:K50)/6 -> 0
C51: Total | F51: =SUM(F47:F50) -> 551.86479 | G51: =SUM(G47:G50) -> 2423.0519 | H51: =SUM(H47:H50) -> 1414.3837 | I51: =SUM(I47:I50) -> 476.06405 | J51: =SUM(J47:J50) -> 2488.66 | K51: =SUM(K47:K50) -> 1037.1636 | L51: =SUM(L47:L50) -> 1141.9422 | M51: =SUM(M47:M50) -> 2246.0612 | ... S51: =SUM(S47:S50) -> 32780.554
C54: Prognosa | F54: =F45 -> 45658 | G54: =G45 -> 45689 | H54: =H45 -> 45717 | I54: =I45 -> 45748 | J54: =J45 -> 45778 | K54: =K45 -> 45809 | L54: =L45 -> 45839 | M54: =M45 -> 45870 | ... Q54: =Q45 -> 45992 | R54: TOTAL | S54: RKAP | T54: %
C55: KBK | F55: =F47 -> 143.32434 | G55: =G47 -> 782.00073 | H55: =H47 -> 681.34313 | I55: =I47 -> 208.7867 | J55: =J47 -> 592.8619 | K55: =K47 -> -74.014673 | L55: =L47 -> 406.85827 | M55: =M47 -> 245.88916 | ... Q55: =Q47 -> 251.4456 | R55: =SUM(F55:Q55) -> 5428.2944 | S55: ='Target Hilirisasi 2025'!AJ9 -> 25000 | T55: =R55/S55 -> 0.21713178
C56: KPI | F56: =F48 -> 64 | G56: =G48 -> 1293 | H56: =H48 -> 366 | I56: =I48 -> 80.334 | J56: =J48 -> 1638.899 | K56: =K48 -> 864.274 | L56: =L48 -> 300 | M56: =M48 -> 1340.533 | ... Q56: =Q48 -> 3953.021 | R56: =SUM(F56:Q56) -> 14083.94 | S56: ='Target Hilirisasi 2025'!AJ10 -> 6804 | T56: =R56/S56 -> 2.06995 | U56: =R56/3 -> 4694.6467
C57: KNI | F57: =F49 -> 344.54045 | G57: =G49 -> 348.05116 | H57: =H49 -> 367.04059 | I57: =I49 -> 186.94335 | J57: =J49 -> 256.8991 | K57: =K49 -> 246.90429 | L57: =L49 -> 435.0839 | M57: =M49 -> 659.639 | ... Q57: =Q49 -> 287.77385 | R57: =SUM(F57:Q57) -> 5890.6043 | S57: ='Target Hilirisasi 2025'!AJ11 -> 5000 | T57: =R57/S57 -> 1.1781209 | U57: =R57/3 -> 1963.5348
C58: KPdP | F58: =F50 -> 0 | G58: =G50 -> 0 | H58: =H50 -> 0 | I58: =I50 -> 0 | J58: =J50 -> 0 | K58: =K50 -> 0 | L58: =L50 -> 0 | M58: =M50 -> 0 | ... Q58: =Q50 -> 0 | R58: =SUM(F58:Q58) -> 0 | S58: ='Target Hilirisasi 2025'!AJ12 -> 0 | T58: =R58/S58 -> #DIV/0!
C59: Total | F59: =SUM(F55:F58) -> 551.86479 | G59: =SUM(G55:G58) -> 2423.0519 | H59: =SUM(H55:H58) -> 1414.3837 | I59: =SUM(I55:I58) -> 476.06405 | J59: =SUM(J55:J58) -> 2488.66 | K59: =SUM(K55:K58) -> 1037.1636 | L59: =SUM(L55:L58) -> 1141.9422 | M59: =SUM(M55:M58) -> 2246.0612 | ... S59: =SUM(S55:S58) -> 36804 | T59: =R59/S59 -> 0.69021951
C62: Prognosa KBK Induk :
N63: =N54 -> 45901 | O63: =O54 -> 45931 | P63: =P54 -> 45962 | Q63: =Q54 -> 45992
C64: Tower & Perkuatan
C65: Modular
C66: Rumah Modular
C67: Steel Construction Project
C68: Steel Based Product
...

Sheet Realisasi Hilirisasi
B2: PT KRAKATAU BAJA KONSTRUKSI
B4: REALISASI HILIRISASI TAHUN 2025
S5: 1 | T5: =S5+1 -> 2 | U5: =T5+1 -> 3 | V5: =U5+1 -> 4 | W5: =V5+1 -> 5 | X5: =W5+1 -> 6 | Y5: =X5+1 -> 7 | Z5: =Y5+1 -> 8 | AA5: =Z5+1 -> 9 | ... AD5: =AC5+1 -> 12
B7: Periode | C7: Entitas | D7: Jenis Produk | E7: Qty | F7: Revenue | G7: Gross Profit | H7: % Margin | I7: HPP | J7: Harga Jual | Q7: Jenis Produk | S7: JAN | T7: FEB | U7: MAR | V7: APR | W7: MEI | X7: JUNI | Y7: JULI | Z7: AGS | AA7: SEP | AB7: OKT | AC7: NOV | AD7: DES | AE7: TOTAL
B8: 1 | C8: KBK | D8: Tower | E8: 12.22994 | F8: 274014772 | G8: 24459880 | H8: =IF(E8=0,0,G8/F8) -> 0.089264823 | I8: =F8-G8 -> 249554892 | J8: =F8/E8 -> 22405243 | Q8: Tower | R8: Ton | S8: =SUMIFS($E:$E,$D:$D,$Q8,$B:$B,S$5) -> 12.22994 | T8: =SUMIFS($E:$E,$D:$D,$Q8,$B:$B,T$5) -> 0 | U8: =SUMIFS($E:$E,$D:$D,$Q8,$B:$B,U$5) -> 27.30362 | V8: =SUMIFS($E:$E,$D:$D,$Q8,$B:$B,V$5) -> 0 | W8: =SUMIFS($E:$E,$D:$D,$Q8,$B:$B,W$5) -> 7.543 | X8: =SUMIFS($E:$E,$D:$D,$Q8,$B:$B,X$5) -> 0 | Y8: =SUMIFS($E:$E,$D:$D,$Q8,$B:$B,Y$5) -> 0 | Z8: =SUMIFS($E:$E,$D:$D,$Q8,$B:$B,Z$5) -> 0 | ... AD8: =SUMIFS($E:$E,$D:$D,$Q8,$B:$B,AD$5) -> 0 | AE8: =SUM(S8:AD8) -> 47.07656 | AF8: =VLOOKUP(Q8,Perbandingan!$B$8:$B$22,1,0) -> Tower
B9: 1 | C9: KBK | D9: Steel Structure | E9: 20.284 | F9: 507100000 | G9: 25355000 | H9: =IF(E9=0,0,G9/F9) -> 0.05 | I9: =F9-G9 -> 481745000 | J9: =F9/E9 -> 25000000 | Q9: Steel Structure | R9: Ton | S9: =SUMIFS($E:$E,$D:$D,$Q9,$B:$B,S$5) -> 20.284 | T9: =SUMIFS($E:$E,$D:$D,$Q9,$B:$B,T$5) -> 605.49788 | U9: =SUMIFS($E:$E,$D:$D,$Q9,$B:$B,U$5) -> 150.3357 | V9: =SUMIFS($E:$E,$D:$D,$Q9,$B:$B,V$5) -> 183.9803 | W9: =SUMIFS($E:$E,$D:$D,$Q9,$B:$B,W$5) -> 215.6683 | X9: =SUMIFS($E:$E,$D:$D,$Q9,$B:$B,X$5) -> -90.577073 | Y9: =SUMIFS($E:$E,$D:$D,$Q9,$B:$B,Y$5) -> 143.38989 | Z9: =SUMIFS($E:$E,$D:$D,$Q9,$B:$B,Z$5) -> 102.66653 | ... AD9: =SUMIFS($E:$E,$D:$D,$Q9,$B:$B,AD$5) -> 92.08198 | AE9: =SUM(S9:AD9) -> 1962.1941 | AF9: =VLOOKUP(Q9,Perbandingan!$B$8:$B$22,1,0) -> Steel Structure
B10: 1 | C10: KBK | D10: Modular | E10: 9.3 | F10: 296250000 | G10: 13950000 | H10: =IF(E10=0,0,G10/F10) -> 0.047088608 | I10: =F10-G10 -> 282300000 | J10: =F10/E10 -> 31854839 | Q10: Modular | R10: Ton | S10: =SUMIFS($E:$E,$D:$D,$Q10,$B:$B,S$5) -> 9.3 | T10: =SUMIFS($E:$E,$D:$D,$Q10,$B:$B,T$5) -> 12.4 | U10: =SUMIFS($E:$E,$D:$D,$Q10,$B:$B,U$5) -> 0 | V10: =SUMIFS($E:$E,$D:$D,$Q10,$B:$B,V$5) -> 0 | W10: =SUMIFS($E:$E,$D:$D,$Q10,$B:$B,W$5) -> 0 | X10: =SUMIFS($E:$E,$D:$D,$Q10,$B:$B,X$5) -> 0 | Y10: =SUMIFS($E:$E,$D:$D,$Q10,$B:$B,Y$5) -> 0 | Z10: =SUMIFS($E:$E,$D:$D,$Q10,$B:$B,Z$5) -> 0 | ... AD10: =SUMIFS($E:$E,$D:$D,$Q10,$B:$B,AD$5) -> 0 | AE10: =SUM(S10:AD10) -> 21.7 | AF10: =VLOOKUP(Q10,Perbandingan!$B$8:$B$22,1,0) -> Modular
B11: 1 | C11: KBK | D11: Steel Component | E11: 101.5104 | F11: 2.2443215e+09 | G11: 199428000 | H11: =IF(E11=0,0,G11/F11) -> 0.088858928 | I11: =F11-G11 -> 2.0448935e+09 | J11: =F11/E11 -> 22109276 | Q11: Steel Component | R11: Ton | S11: =SUMIFS($E:$E,$D:$D,$Q11,$B:$B,S$5) -> 101.5104 | T11: =SUMIFS($E:$E,$D:$D,$Q11,$B:$B,T$5) -> 164.10286 | U11: =SUMIFS($E:$E,$D:$D,$Q11,$B:$B,U$5) -> 503.70381 | V11: =SUMIFS($E:$E,$D:$D,$Q11,$B:$B,V$5) -> 24.8064 | W11: =SUMIFS($E:$E,$D:$D,$Q11,$B:$B,W$5) -> 369.6506 | X11: =SUMIFS($E:$E,$D:$D,$Q11,$B:$B,X$5) -> 16.5624 | Y11: =SUMIFS($E:$E,$D:$D,$Q11,$B:$B,Y$5) -> 263.46838 | Z11: =SUMIFS($E:$E,$D:$D,$Q11,$B:$B,Z$5) -> 143.22263 | ... AD11: =SUMIFS($E:$E,$D:$D,$Q11,$B:$B,AD$5) -> 159.36362 | AE11: =SUM(S11:AD11) -> 3397.3238 | AF11: =VLOOKUP(Q11,Perbandingan!$B$8:$B$22,1,0) -> Steel Component
B12: 1 | C12: KBK | D12: Cut to Length | H12: =IF(E12=0,0,G12/F12) -> 0 | I12: =F12-G12 -> 0 | J12: =F12/E12 -> #DIV/0! | Q12: Cut to Length | R12: Ton | S12: =SUMIFS($E:$E,$D:$D,$Q12,$B:$B,S$5) -> 0 | T12: =SUMIFS($E:$E,$D:$D,$Q12,$B:$B,T$5) -> 0 | U12: =SUMIFS($E:$E,$D:$D,$Q12,$B:$B,U$5) -> 0 | V12: =SUMIFS($E:$E,$D:$D,$Q12,$B:$B,V$5) -> 0 | W12: =SUMIFS($E:$E,$D:$D,$Q12,$B:$B,W$5) -> 0 | X12: =SUMIFS($E:$E,$D:$D,$Q12,$B:$B,X$5) -> 0 | Y12: =SUMIFS($E:$E,$D:$D,$Q12,$B:$B,Y$5) -> 0 | Z12: =SUMIFS($E:$E,$D:$D,$Q12,$B:$B,Z$5) -> 0 | ... AD12: =SUMIFS($E:$E,$D:$D,$Q12,$B:$B,AD$5) -> 0 | AE12: =SUM(S12:AD12) -> 0 | AF12: =VLOOKUP(Q12,Perbandingan!$B$8:$B$22,1,0) -> Cut to Length
B13: 1 | C13: KPI | D13: Tiang Listrik | E13: 64 | F13: 979039135 | G13: 15861300 | H13: =IF(E13=0,0,G13/F13) -> 0.016200885 | I13: =F13-G13 -> 963177835 | J13: =F13/E13 -> 15297486 | Q13: Tiang Listrik | R13: Ton | S13: =SUMIFS($E:$E,$D:$D,$Q13,$B:$B,S$5) -> 64 | T13: =SUMIFS($E:$E,$D:$D,$Q13,$B:$B,T$5) -> 194 | U13: =SUMIFS($E:$E,$D:$D,$Q13,$B:$B,U$5) -> 366 | V13: =SUMIFS($E:$E,$D:$D,$Q13,$B:$B,V$5) -> 80.334 | W13: =SUMIFS($E:$E,$D:$D,$Q13,$B:$B,W$5) -> 144.718 | X13: =SUMIFS($E:$E,$D:$D,$Q13,$B:$B,X$5) -> 362.842 | Y13: =SUMIFS($E:$E,$D:$D,$Q13,$B:$B,Y$5) -> 300 | Z13: =SUMIFS($E:$E,$D:$D,$Q13,$B:$B,Z$5) -> 260.533 | ... AD13: =SUMIFS($E:$E,$D:$D,$Q13,$B:$B,AD$5) -> 47.42 | AE13: =SUM(S13:AD13) -> 2303.927 | AF13: =VLOOKUP(Q13,Perbandingan!$B$8:$B$22,1,0) -> Tiang Listrik
B14: 1 | C14: KPI | D14: Tiang FO / Telkom | H14: =IF(E14=0,0,G14/F14) -> 0 | I14: =F14-G14 -> 0 | J14: =F14/E14 -> #DIV/0! | Q14: Tiang FO / Telkom | R14: Ton | S14: =SUMIFS($E:$E,$D:$D,$Q14,$B:$B,S$5) -> 0 | T14: =SUMIFS($E:$E,$D:$D,$Q14,$B:$B,T$5) -> 0 | U14: =SUMIFS($E:$E,$D:$D,$Q14,$B:$B,U$5) -> 0 | V14: =SUMIFS($E:$E,$D:$D,$Q14,$B:$B,V$5) -> 0 | W14: =SUMIFS($E:$E,$D:$D,$Q14,$B:$B,W$5) -> 0 | X14: =SUMIFS($E:$E,$D:$D,$Q14,$B:$B,X$5) -> 0 | Y14: =SUMIFS($E:$E,$D:$D,$Q14,$B:$B,Y$5) -> 0 | Z14: =SUMIFS($E:$E,$D:$D,$Q14,$B:$B,Z$5) -> 0 | ... AD14: =SUMIFS($E:$E,$D:$D,$Q14,$B:$B,AD$5) -> 0 | AE14: =SUM(S14:AD14) -> 0 | AF14: =VLOOKUP(Q14,Perbandingan!$B$8:$B$22,1,0) -> Tiang FO / Telkom
B15: 1 | C15: KPI | D15: Pipe Bends | H15: =IF(E15=0,0,G15/F15) -> 0 | I15: =F15-G15 -> 0 | J15: =F15/E15 -> #DIV/0! | Q15: Pipe Bends | R15: Ton | S15: =SUMIFS($E:$E,$D:$D,$Q15,$B:$B,S$5) -> 0 | T15: =SUMIFS($E:$E,$D:$D,$Q15,$B:$B,T$5) -> 101 | U15: =SUMIFS($E:$E,$D:$D,$Q15,$B:$B,U$5) -> 0 | V15: =SUMIFS($E:$E,$D:$D,$Q15,$B:$B,V$5) -> 0 | W15: =SUMIFS($E:$E,$D:$D,$Q15,$B:$B,W$5) -> 0 | X15: =SUMIFS($E:$E,$D:$D,$Q15,$B:$B,X$5) -> 0 | Y15: =SUMIFS($E:$E,$D:$D,$Q15,$B:$B,Y$5) -> 0 | Z15: =SUMIFS($E:$E,$D:$D,$Q15,$B:$B,Z$5) -> 11 | ... AD15: =SUMIFS($E:$E,$D:$D,$Q15,$B:$B,AD$5) -> 0 | AE15: =SUM(S15:AD15) -> 112 | AF15: =VLOOKUP(Q15,Perbandingan!$B$8:$B$22,1,0) -> Pipe Bends
B16: 1 | C16: KNI | D16: Baja Ringan | E16: 271.52938 | F16: 4.5398547e+09 | G16: 68097820 | H16: =IF(E16=0,0,G16/F16) -> 0.015 | I16: =F16-G16 -> 4.4717569e+09 | J16: =F16/E16 -> 16719571 | Q16: Seamless Pipe | R16: Ton | S16: =SUMIFS($E:$E,$D:$D,$Q16,$B:$B,S$5) -> 0 | T16: =SUMIFS($E:$E,$D:$D,$Q16,$B:$B,T$5) -> 998 | U16: =SUMIFS($E:$E,$D:$D,$Q16,$B:$B,U$5) -> 0 | V16: =SUMIFS($E:$E,$D:$D,$Q16,$B:$B,V$5) -> 0 | W16: =SUMIFS($E:$E,$D:$D,$Q16,$B:$B,W$5) -> 1494.181 | X16: =SUMIFS($E:$E,$D:$D,$Q16,$B:$B,X$5) -> 501.432 | Y16: =SUMIFS($E:$E,$D:$D,$Q16,$B:$B,Y$5) -> 0 | Z16: =SUMIFS($E:$E,$D:$D,$Q16,$B:$B,Z$5) -> 1069 | ... AD16: =SUMIFS($E:$E,$D:$D,$Q16,$B:$B,AD$5) -> 3905.601 | AE16: =SUM(S16:AD16) -> 11668.013 | AF16: Seamless Pipe
B17: 1 | C17: KNI | D17: Floordeck | H17: =IF(E17=0,0,G17/F17) -> 0 | I17: =F17-G17 -> 0 | J17: =F17/E17 -> #DIV/0! | Q17: Baja Ringan | R17: Ton | S17: =SUMIFS($E:$E,$D:$D,$Q17,$B:$B,S$5) -> 271.52938 | T17: =SUMIFS($E:$E,$D:$D,$Q17,$B:$B,T$5) -> 216.95636 | U17: =SUMIFS($E:$E,$D:$D,$Q17,$B:$B,U$5) -> 271.65959 | V17: =SUMIFS($E:$E,$D:$D,$Q17,$B:$B,V$5) -> 181.288 | W17: =SUMIFS($E:$E,$D:$D,$Q17,$B:$B,W$5) -> 256.8991 | X17: =SUMIFS($E:$E,$D:$D,$Q17,$B:$B,X$5) -> 246.90429 | Y17: =SUMIFS($E:$E,$D:$D,$Q17,$B:$B,Y$5) -> 377.3549 | Z17: =SUMIFS($E:$E,$D:$D,$Q17,$B:$B,Z$5) -> 385.53195 | ... AD17: =SUMIFS($E:$E,$D:$D,$Q17,$B:$B,AD$5) -> 279.90685 | AE17: =SUM(S17:AD17) -> 3565.0796 | AF17: =VLOOKUP(Q17,Perbandingan!$B$8:$B$22,1,0) -> Baja Ringan
B18: 1 | C18: KNI | D18: Galvalum | H18: =IF(E18=0,0,G18/F18) -> 0 | I18: =F18-G18 -> 0 | J18: =F18/E18 -> #DIV/0! | Q18: Floordeck | R18: Ton | S18: =SUMIFS($E:$E,$D:$D,$Q18,$B:$B,S$5) -> 0 | T18: =SUMIFS($E:$E,$D:$D,$Q18,$B:$B,T$5) -> 0 | U18: =SUMIFS($E:$E,$D:$D,$Q18,$B:$B,U$5) -> 0 | V18: =SUMIFS($E:$E,$D:$D,$Q18,$B:$B,V$5) -> 0 | W18: =SUMIFS($E:$E,$D:$D,$Q18,$B:$B,W$5) -> 0 | X18: =SUMIFS($E:$E,$D:$D,$Q18,$B:$B,X$5) -> 0 | Y18: =SUMIFS($E:$E,$D:$D,$Q18,$B:$B,Y$5) -> 0 | Z18: =SUMIFS($E:$E,$D:$D,$Q18,$B:$B,Z$5) -> 0 | ... AD18: =SUMIFS($E:$E,$D:$D,$Q18,$B:$B,AD$5) -> 0 | AE18: =SUM(S18:AD18) -> 0 | AF18: =VLOOKUP(Q18,Perbandingan!$B$8:$B$22,1,0) -> #N/A
B19: 1 | C19: KNI | D19: CNP | E19: 1.676 | F19: 25936100 | G19: 5690020 | H19: =IF(E19=0,0,G19/F19) -> 0.21938611 | I19: =F19-G19 -> 20246080 | J19: =F19/E19 -> 15475000 | Q19: Galvalum | R19: Ton | S19: =SUMIFS($E:$E,$D:$D,$Q19,$B:$B,S$5) -> 0 | T19: =SUMIFS($E:$E,$D:$D,$Q19,$B:$B,T$5) -> 0 | U19: =SUMIFS($E:$E,$D:$D,$Q19,$B:$B,U$5) -> 0 | V19: =SUMIFS($E:$E,$D:$D,$Q19,$B:$B,V$5) -> 0 | W19: =SUMIFS($E:$E,$D:$D,$Q19,$B:$B,W$5) -> 0 | X19: =SUMIFS($E:$E,$D:$D,$Q19,$B:$B,X$5) -> 0 | Y19: =SUMIFS($E:$E,$D:$D,$Q19,$B:$B,Y$5) -> 0 | Z19: =SUMIFS($E:$E,$D:$D,$Q19,$B:$B,Z$5) -> 0 | ... AD19: =SUMIFS($E:$E,$D:$D,$Q19,$B:$B,AD$5) -> 0 | AE19: =SUM(S19:AD19) -> 0 | AF19: =VLOOKUP(Q19,Perbandingan!$B$8:$B$22,1,0) -> Galvalum
B20: 1 | C20: KNI | D20: Lain-Lain KNI | E20: 71.33507 | F20: 9.1263068e+08 | G20: 44877781 | H20: =IF(E20=0,0,G20/F20) -> 0.049174087 | I20: =F20-G20 -> 8.677529e+08 | J20: =F20/E20 -> 12793577 | Q20: CNP | R20: Ton | S20: =SUMIFS($E:$E,$D:$D,$Q20,$B:$B,S$5) -> 1.676 | T20: =SUMIFS($E:$E,$D:$D,$Q20,$B:$B,T$5) -> 3.065 | U20: =SUMIFS($E:$E,$D:$D,$Q20,$B:$B,U$5) -> 0 | V20: =SUMIFS($E:$E,$D:$D,$Q20,$B:$B,V$5) -> 0 | W20: =SUMIFS($E:$E,$D:$D,$Q20,$B:$B,W$5) -> 0 | X20: =SUMIFS($E:$E,$D:$D,$Q20,$B:$B,X$5) -> 0 | Y20: =SUMIFS($E:$E,$D:$D,$Q20,$B:$B,Y$5) -> 0 | Z20: =SUMIFS($E:$E,$D:$D,$Q20,$B:$B,Z$5) -> 0.8974 | ... AD20: =SUMIFS($E:$E,$D:$D,$Q20,$B:$B,AD$5) -> 7.867 | AE20: =SUM(S20:AD20) -> 137.2224 | AF20: =VLOOKUP(Q20,Perbandingan!$B$8:$B$22,1,0) -> CNP
B21: 1 | C21: KPdP | D21: Welded Beam & Custom Product | H21: =IF(E21=0,0,G21/F21) -> 0 | I21: =F21-G21 -> 0 | J21: =F21/E21 -> #DIV/0! | Q21: Lain-Lain KNI | R21: Ton | S21: =SUMIFS($E:$E,$D:$D,$Q21,$B:$B,S$5) -> 71.33507 | T21: =SUMIFS($E:$E,$D:$D,$Q21,$B:$B,T$5) -> 128.0298 | U21: =SUMIFS($E:$E,$D:$D,$Q21,$B:$B,U$5) -> 95.381 | V21: =SUMIFS($E:$E,$D:$D,$Q21,$B:$B,V$5) -> 5.65535 | W21: =SUMIFS($E:$E,$D:$D,$Q21,$B:$B,W$5) -> 0 | X21: =SUMIFS($E:$E,$D:$D,$Q21,$B:$B,X$5) -> 0 | Y21: =SUMIFS($E:$E,$D:$D,$Q21,$B:$B,Y$5) -> 57.729 | Z21: =SUMIFS($E:$E,$D:$D,$Q21,$B:$B,Z$5) -> 273.20965 | ... AD21: =SUMIFS($E:$E,$D:$D,$Q21,$B:$B,AD$5) -> 0 | AE21: =SUM(S21:AD21) -> 2188.3023 | AF21: =VLOOKUP(Q21,Perbandingan!$B$8:$B$22,1,0) -> Lain-Lain KNI
B22: 2 | C22: KBK | D22: Tower | H22: =IF(E22=0,0,G22/F22) -> 0 | I22: =F22-G22 -> 0 | J22: =F22/E22 -> #DIV/0! | Q22: Welded Beam & Custom Product | R22: Ton | S22: =SUMIFS($E:$E,$D:$D,$Q22,$B:$B,S$5) -> 0 | T22: =SUMIFS($E:$E,$D:$D,$Q22,$B:$B,T$5) -> 0 | U22: =SUMIFS($E:$E,$D:$D,$Q22,$B:$B,U$5) -> 0 | V22: =SUMIFS($E:$E,$D:$D,$Q22,$B:$B,V$5) -> 0 | W22: =SUMIFS($E:$E,$D:$D,$Q22,$B:$B,W$5) -> 0 | X22: =SUMIFS($E:$E,$D:$D,$Q22,$B:$B,X$5) -> 0 | Y22: =SUMIFS($E:$E,$D:$D,$Q22,$B:$B,Y$5) -> 0 | Z22: =SUMIFS($E:$E,$D:$D,$Q22,$B:$B,Z$5) -> 0 | ... AD22: =SUMIFS($E:$E,$D:$D,$Q22,$B:$B,AD$5) -> 0 | AE22: =SUM(S22:AD22) -> 0 | AF22: =VLOOKUP(Q22,Perbandingan!$B$8:$B$22,1,0) -> Welded Beam & Custom Product
B23: =$B$22 -> 2 | C23: KBK | D23: Steel Structure | E23: 605.49788 | F23: 12675111281 | G23: 6.0549788e+08 | H23: =IF(E23=0,0,G23/F23) -> 0.047770616 | I23: =F23-G23 -> 1.2069613e+10 | J23: =F23/E23 -> 20933370
B24: =$B$22 -> 2 | C24: KBK | D24: Modular | E24: 12.4 | F24: 395000000 | G24: 12400000 | H24: =IF(E24=0,0,G24/F24) -> 0.031392405 | I24: =F24-G24 -> 382600000 | J24: =F24/E24 -> 31854839 | Q24: TOTAL | R24: Ton | S24: =SUM(S8:S23) -> 551.86479 | T24: =SUM(T8:T23) -> 2423.0519 | U24: =SUM(U8:U23) -> 1414.3837 | V24: =SUM(V8:V23) -> 476.06405 | W24: =SUM(W8:W23) -> 2488.66 | X24: =SUM(X8:X23) -> 1037.1636 | Y24: =SUM(Y8:Y23) -> 1141.9422 | Z24: =SUM(Z8:Z23) -> 2246.0612 | ... AE24: =SUM(AE8:AE23) -> 25402.839
B25: =$B$22 -> 2 | C25: KBK | D25: Steel Component | E25: 164.10286 | F25: 2.4385311e+09 | G25: 3.5629816e+08 | H25: =IF(E25=0,0,G25/F25) -> 0.14611179 | I25: =F25-G25 -> 2.082233e+09 | J25: =F25/E25 -> 14859772
B26: =$B$22 -> 2 | C26: KBK | D26: Cut to Length | H26: =IF(E26=0,0,G26/F26) -> 0 | I26: =F26-G26 -> 0 | J26: =F26/E26 -> #DIV/0!
B27: =$B$22 -> 2 | C27: KPI | D27: Tiang Listrik | E27: 194 | F27: 3350711687 | G27: 48398130 | H27: =IF(E27=0,0,G27/F27) -> 0.014444134 | I27: =F27-G27 -> 3302313557 | J27: =F27/E27 -> 17271710 | Q27: Entitas | S27: JAN | T27: FEB | U27: MAR | V27: APR | W27: MEI | X27: JUNI | Y27: JULI | Z27: AGS | AA27: SEP | AB27: OKT | AC27: NOV | AD27: DES | AE27: TOTAL | AF27: TARGET | AG27: %
B28: =$B$22 -> 2 | C28: KPI | D28: Tiang FO / Telkom | H28: =IF(E28=0,0,G28/F28) -> 0 | I28: =F28-G28 -> 0 | J28: =F28/E28 -> #DIV/0! | Q28: KBK | R28: Ton | S28: =SUMIFS($E:$E,$C:$C,$Q28,$B:$B,S$5) -> 143.32434 | T28: =SUMIFS($E:$E,$C:$C,$Q28,$B:$B,T$5) -> 782.00073 | U28: =SUMIFS($E:$E,$C:$C,$Q28,$B:$B,U$5) -> 681.34313 | V28: =SUMIFS($E:$E,$C:$C,$Q28,$B:$B,V$5) -> 208.7867 | W28: =SUMIFS($E:$E,$C:$C,$Q28,$B:$B,W$5) -> 592.8619 | X28: =SUMIFS($E:$E,$C:$C,$Q28,$B:$B,X$5) -> -74.014673 | Y28: =SUMIFS($E:$E,$C:$C,$Q28,$B:$B,Y$5) -> 406.85827 | Z28: =SUMIFS($E:$E,$C:$C,$Q28,$B:$B,Z$5) -> 245.88916 | ... AD28: =SUMIFS($E:$E,$C:$C,$Q28,$B:$B,AD$5) -> 251.4456 | AE28: =SUM(S28:AD28) -> 5428.2944 | AF28: =SUM('Target Hilirisasi 2025'!E9:P9) -> 25000 | AG28: =AE28/AF28 -> 0.21713178
B29: =$B$22 -> 2 | C29: KPI | D29: Pipe Bends | E29: 101 | F29: 7914861631 | G29: 2642350040 | H29: =IF(E29=0,0,G29/F29) -> 0.33384665 | I29: =F29-G29 -> 5272511591 | J29: =F29/E29 -> 78364967 | Q29: KPI | R29: Ton | S29: =SUMIFS($E:$E,$C:$C,$Q29,$B:$B,S$5) -> 64 | T29: =SUMIFS($E:$E,$C:$C,$Q29,$B:$B,T$5) -> 1293 | U29: =SUMIFS($E:$E,$C:$C,$Q29,$B:$B,U$5) -> 366 | V29: =SUMIFS($E:$E,$C:$C,$Q29,$B:$B,V$5) -> 80.334 | W29: =SUMIFS($E:$E,$C:$C,$Q29,$B:$B,W$5) -> 1638.899 | X29: =SUMIFS($E:$E,$C:$C,$Q29,$B:$B,X$5) -> 864.274 | Y29: =SUMIFS($E:$E,$C:$C,$Q29,$B:$B,Y$5) -> 300 | Z29: =SUMIFS($E:$E,$C:$C,$Q29,$B:$B,Z$5) -> 1340.533 | ... AD29: =SUMIFS($E:$E,$C:$C,$Q29,$B:$B,AD$5) -> 3953.021 | AE29: =SUM(S29:AD29) -> 14083.94 | AF29: =SUM('Target Hilirisasi 2025'!E10:P10) -> 6804 | AG29: =AE29/AF29 -> 2.06995
B30: =$B$22 -> 2 | C30: KPI | D30: Seamless Pipe | E30: 998 | F30: 14078574228 | G30: 2994405000 | H30: =IF(E30=0,0,G30/F30) -> 0.21269235 | I30: =F30-G30 -> 11084169228 | J30: =F30/E30 -> 14106788 | Q30: KNI | R30: Ton | S30: =SUMIFS($E:$E,$C:$C,$Q30,$B:$B,S$5) -> 344.54045 | T30: =SUMIFS($E:$E,$C:$C,$Q30,$B:$B,T$5) -> 348.05116 | U30: =SUMIFS($E:$E,$C:$C,$Q30,$B:$B,U$5) -> 367.04059 | V30: =SUMIFS($E:$E,$C:$C,$Q30,$B:$B,V$5) -> 186.94335 | W30: =SUMIFS($E:$E,$C:$C,$Q30,$B:$B,W$5) -> 256.8991 | X30: =SUMIFS($E:$E,$C:$C,$Q30,$B:$B,X$5) -> 246.90429 | Y30: =SUMIFS($E:$E,$C:$C,$Q30,$B:$B,Y$5) -> 435.0839 | Z30: =SUMIFS($E:$E,$C:$C,$Q30,$B:$B,Z$5) -> 659.639 | ... AD30: =SUMIFS($E:$E,$C:$C,$Q30,$B:$B,AD$5) -> 287.77385 | AE30: =SUM(S30:AD30) -> 5890.6043 | AF30: =SUM('Target Hilirisasi 2025'!E11:P11) -> 5000 | AG30: =AE30/AF30 -> 1.1781209
B31: =$B$22 -> 2 | C31: KNI | D31: Baja Ringan | E31: 216.95636 | F31: 3.7170599e+09 | G31: 54931919 | H31: =IF(E31=0,0,G31/F31) -> 0.014778325 | I31: =F31-G31 -> 3.6621279e+09 | J31: =F31/E31 -> 17132753 | Q31: KPdP | R31: Ton | S31: =SUMIFS($E:$E,$C:$C,$Q31,$B:$B,S$5) -> 0 | T31: =SUMIFS($E:$E,$C:$C,$Q31,$B:$B,T$5) -> 0 | U31: =SUMIFS($E:$E,$C:$C,$Q31,$B:$B,U$5) -> 0 | V31: =SUMIFS($E:$E,$C:$C,$Q31,$B:$B,V$5) -> 0 | W31: =SUMIFS($E:$E,$C:$C,$Q31,$B:$B,W$5) -> 0 | X31: =SUMIFS($E:$E,$C:$C,$Q31,$B:$B,X$5) -> 0 | Y31: =SUMIFS($E:$E,$C:$C,$Q31,$B:$B,Y$5) -> 0 | Z31: =SUMIFS($E:$E,$C:$C,$Q31,$B:$B,Z$5) -> 0 | ... AD31: =SUMIFS($E:$E,$C:$C,$Q31,$B:$B,AD$5) -> 0 | AE31: =SUM(S31:AD31) -> 0 | AG31: =AE31/AF31 -> #DIV/0!
B32: =$B$22 -> 2 | C32: KNI | D32: Floordeck | H32: =IF(E32=0,0,G32/F32) -> 0 | I32: =F32-G32 -> 0 | J32: =F32/E32 -> #DIV/0! | AG32: =AE32/AF32 -> #DIV/0!
B33: =$B$22 -> 2 | C33: KNI | D33: Galvalum | H33: =IF(E33=0,0,G33/F33) -> 0 | I33: =F33-G33 -> 0 | J33: =F33/E33 -> #DIV/0! | AG33: =AE33/AF33 -> #DIV/0!
B34: =$B$22 -> 2 | C34: KNI | D34: CNP | E34: 3.065 | F34: 38651610 | G34: 3514189 | H34: =IF(E34=0,0,G34/F34) -> 0.090919602 | I34: =F34-G34 -> 35137421 | J34: =F34/E34 -> 12610639 | Q34: TOTAL | R34: Ton | S34: =SUM(S28:S33) -> 551.86479 | T34: =SUM(T28:T33) -> 2423.0519 | U34: =SUM(U28:U33) -> 1414.3837 | V34: =SUM(V28:V33) -> 476.06405 | W34: =SUM(W28:W33) -> 2488.66 | X34: =SUM(X28:X33) -> 1037.1636 | Y34: =SUM(Y28:Y33) -> 1141.9422 | Z34: =SUM(Z28:Z33) -> 2246.0612 | ... AF34: =SUM(AF28:AF33) -> 36804 | AG34: =AE34/AF34 -> 0.69021951
B35: =$B$22 -> 2 | C35: KNI | D35: Lain-Lain KNI | E35: 128.0298 | F35: 1888065028 | G35: 195964576 | H35: =IF(E35=0,0,G35/F35) -> 0.10379122 | I35: =F35-G35 -> 1692100452 | J35: =F35/E35 -> 14747075
B36: =$B$22 -> 2 | C36: KPdP | D36: Welded Beam & Custom Product | H36: =IF(E36=0,0,G36/F36) -> 0 | I36: =F36-G36 -> 0 | J36: =F36/E36 -> #DIV/0!
B37: 3 | C37: KBK | D37: Tower | E37: 27.30362 | F37: 646391564 | G37: 54607240 | H37: =IF(E37=0,0,G37/F37) -> 0.084480125 | I37: =F37-G37 -> 591784324 | J37: =F37/E37 -> 23674207
B38: 3 | C38: KBK | D38: Steel Structure | E38: 150.3357 | F38: 2588842425 | G38: 1.6411604e+08 | H38: =IF(E38=0,0,G38/F38) -> 0.063393601 | I38: =F38-G38 -> 2.4247264e+09 | J38: =F38/E38 -> 17220410
B39: 3 | C39: KBK | D39: Modular | H39: =IF(E39=0,0,G39/F39) -> 0 | I39: =F39-G39 -> 0 | J39: =F39/E39 -> #DIV/0! | Q39: HPP | S39: JAN | T39: FEB | U39: MAR | V39: APR | W39: MEI | X39: JUNI | Y39: JULI | Z39: AGS | AA39: SEP | AB39: OKT | AC39: NOV | AD39: DES | AE39: TOTAL
B40: 3 | C40: KBK | D40: Steel Component | E40: 503.70381 | F40: 3.5778199e+09 | G40: 4.4962193e+08 | H40: =IF(E40=0,0,G40/F40) -> 0.12566924 | I40: =F40-G40 -> 3.128198e+09 | J40: =F40/E40 -> 7103023.5 | Q40: KBK | R40: Rp Juta | S40: =SUMIFS($I:$I,$C:$C,$Q40,$B:$B,S$5)/1000000 -> 3058.4934 | T40: =SUMIFS($I:$I,$C:$C,$Q40,$B:$B,T$5)/1000000 -> 14534.446 | U40: =SUMIFS($I:$I,$C:$C,$Q40,$B:$B,U$5)/1000000 -> 6144.7087 | V40: =SUMIFS($I:$I,$C:$C,$Q40,$B:$B,V$5)/1000000 -> 5763.212 | W40: =SUMIFS($I:$I,$C:$C,$Q40,$B:$B,W$5)/1000000 -> 11701.229 | X40: =SUMIFS($I:$I,$C:$C,$Q40,$B:$B,X$5)/1000000 -> -2217.6868 | Y40: =SUMIFS($I:$I,$C:$C,$Q40,$B:$B,Y$5)/1000000 -> 7664.4114 | Z40: =SUMIFS($I:$I,$C:$C,$Q40,$B:$B,Z$5)/1000000 -> 5855.5707 | ... AD40: =SUMIFS($I:$I,$C:$C,$Q40,$B:$B,AD$5)/1000000 -> 6851.996 | AE40: =SUM(S40:AD40) -> 103627.85
B41: 3 | C41: KBK | D41: Cut to Length | H41: =IF(E41=0,0,G41/F41) -> 0 | I41: =F41-G41 -> 0 | J41: =F41/E41 -> #DIV/0! | Q41: KPI | R41: Rp Juta | S41: =SUMIFS($I:$I,$C:$C,$Q41,$B:$B,S$5)/1000000 -> 963.17783 | T41: =SUMIFS($I:$I,$C:$C,$Q41,$B:$B,T$5)/1000000 -> 19658.994 | U41: =SUMIFS($I:$I,$C:$C,$Q41,$B:$B,U$5)/1000000 -> 6815.9053 | V41: =SUMIFS($I:$I,$C:$C,$Q41,$B:$B,V$5)/1000000 -> 1394.148 | W41: =SUMIFS($I:$I,$C:$C,$Q41,$B:$B,W$5)/1000000 -> 18755.55 | X41: =SUMIFS($I:$I,$C:$C,$Q41,$B:$B,X$5)/1000000 -> 11544.614 | Y41: =SUMIFS($I:$I,$C:$C,$Q41,$B:$B,Y$5)/1000000 -> 5298.1115 | Z41: =SUMIFS($I:$I,$C:$C,$Q41,$B:$B,Z$5)/1000000 -> 15131.287 | ... AD41: =SUMIFS($I:$I,$C:$C,$Q41,$B:$B,AD$5)/1000000 -> 41499.591 | AE41: =SUM(S41:AD41) -> 166030.74
B42: 3 | C42: KPI | D42: Tiang Listrik | E42: 366 | F42: 6.9069412e+09 | G42: 91035894 | H42: =IF(E42=0,0,G42/F42) -> 0.013180349 | I42: =F42-G42 -> 6.8159053e+09 | J42: =F42/E42 -> 18871424 | Q42: KNI | R42: Rp Juta | S42: =SUMIFS($I:$I,$C:$C,$Q42,$B:$B,S$5)/1000000 -> 5359.7558 | T42: =SUMIFS($I:$I,$C:$C,$Q42,$B:$B,T$5)/1000000 -> 5389.3658 | U42: =SUMIFS($I:$I,$C:$C,$Q42,$B:$B,U$5)/1000000 -> 5791.7095 | V42: =SUMIFS($I:$I,$C:$C,$Q42,$B:$B,V$5)/1000000 -> 3119.5053 | W42: =SUMIFS($I:$I,$C:$C,$Q42,$B:$B,W$5)/1000000 -> 4186.3775 | X42: =SUMIFS($I:$I,$C:$C,$Q42,$B:$B,X$5)/1000000 -> 4045.9604 | Y42: =SUMIFS($I:$I,$C:$C,$Q42,$B:$B,Y$5)/1000000 -> 6851.3747 | Z42: =SUMIFS($I:$I,$C:$C,$Q42,$B:$B,Z$5)/1000000 -> 204.3638 | ... AD42: =SUMIFS($I:$I,$C:$C,$Q42,$B:$B,AD$5)/1000000 -> 4776.4035 | AE42: =SUM(S42:AD42) -> 74224.676
B43: 3 | C43: KPI | D43: Tiang FO / Telkom | H43: =IF(E43=0,0,G43/F43) -> 0 | I43: =F43-G43 -> 0 | J43: =F43/E43 -> #DIV/0! | Q43: KPdP | R43: Rp Juta | S43: =SUMIFS($I:$I,$C:$C,$Q43,$B:$B,S$5)/1000000 -> 0 | T43: =SUMIFS($I:$I,$C:$C,$Q43,$B:$B,T$5)/1000000 -> 0 | U43: =SUMIFS($I:$I,$C:$C,$Q43,$B:$B,U$5)/1000000 -> 0 | V43: =SUMIFS($I:$I,$C:$C,$Q43,$B:$B,V$5)/1000000 -> 0 | W43: =SUMIFS($I:$I,$C:$C,$Q43,$B:$B,W$5)/1000000 -> 0 | X43: =SUMIFS($I:$I,$C:$C,$Q43,$B:$B,X$5)/1000000 -> 0 | Y43: =SUMIFS($I:$I,$C:$C,$Q43,$B:$B,Y$5)/1000000 -> 0 | Z43: =SUMIFS($I:$I,$C:$C,$Q43,$B:$B,Z$5)/1000000 -> 0 | ... AD43: =SUMIFS($I:$I,$C:$C,$Q43,$B:$B,AD$5)/1000000 -> 0 | AE43: =SUM(S43:AD43) -> 0
...

Sheet Resume
B4: Jenis Produk | C4: Qty (Ton) | D4: Revenue (Rp Milyar) | E4: Gross Profit (Rp Milyar)
B5: Tower | C5: =SUMIF('Realisasi Hilirisasi'!$D:$D,Resume!$B5,'Realisasi Hilirisasi'!E:E) -> 47.07656 | D5: =SUMIF('Realisasi Hilirisasi'!$D:$D,Resume!$B5,'Realisasi Hilirisasi'!F:F)/1000000000 -> 1.1010626 | E5: =SUMIF('Realisasi Hilirisasi'!$D:$D,Resume!$B5,'Realisasi Hilirisasi'!G:G)/1000000000 -> 0.09359192
B6: Steel Structure | C6: =SUMIF('Realisasi Hilirisasi'!$D:$D,Resume!$B6,'Realisasi Hilirisasi'!E:E) -> 1962.1941 | D6: =SUMIF('Realisasi Hilirisasi'!$D:$D,Resume!$B6,'Realisasi Hilirisasi'!F:F)/1000000000 -> 59.722105 | E6: =SUMIF('Realisasi Hilirisasi'!$D:$D,Resume!$B6,'Realisasi Hilirisasi'!G:G)/1000000000 -> 0.81948819
B7: Modular | C7: =SUMIF('Realisasi Hilirisasi'!$D:$D,Resume!$B7,'Realisasi Hilirisasi'!E:E) -> 21.7 | D7: =SUMIF('Realisasi Hilirisasi'!$D:$D,Resume!$B7,'Realisasi Hilirisasi'!F:F)/1000000000 -> 0.69125 | E7: =SUMIF('Realisasi Hilirisasi'!$D:$D,Resume!$B7,'Realisasi Hilirisasi'!G:G)/1000000000 -> 0.02635
B8: Steel Component | C8: =SUMIF('Realisasi Hilirisasi'!$D:$D,Resume!$B8,'Realisasi Hilirisasi'!E:E) -> 3397.3238 | D8: =SUMIF('Realisasi Hilirisasi'!$D:$D,Resume!$B8,'Realisasi Hilirisasi'!F:F)/1000000000 -> 45.352707 | E8: =SUMIF('Realisasi Hilirisasi'!$D:$D,Resume!$B8,'Realisasi Hilirisasi'!G:G)/1000000000 -> 2.299841
B9: Cut to Length | C9: =SUMIF('Realisasi Hilirisasi'!$D:$D,Resume!$B9,'Realisasi Hilirisasi'!E:E) -> 0 | D9: =SUMIF('Realisasi Hilirisasi'!$D:$D,Resume!$B9,'Realisasi Hilirisasi'!F:F)/1000000000 -> 0 | E9: =SUMIF('Realisasi Hilirisasi'!$D:$D,Resume!$B9,'Realisasi Hilirisasi'!G:G)/1000000000 -> 0
B10: Tiang Listrik | C10: =SUMIF('Realisasi Hilirisasi'!$D:$D,Resume!$B10,'Realisasi Hilirisasi'!E:E) -> 2303.927 | D10: =SUMIF('Realisasi Hilirisasi'!$D:$D,Resume!$B10,'Realisasi Hilirisasi'!F:F)/1000000000 -> 41.300999 | E10: =SUMIF('Realisasi Hilirisasi'!$D:$D,Resume!$B10,'Realisasi Hilirisasi'!G:G)/1000000000 -> 1.2537361
B11: Tiang FO / Telkom | C11: =SUMIF('Realisasi Hilirisasi'!$D:$D,Resume!$B11,'Realisasi Hilirisasi'!E:E) -> 0 | D11: =SUMIF('Realisasi Hilirisasi'!$D:$D,Resume!$B11,'Realisasi Hilirisasi'!F:F)/1000000000 -> 0 | E11: =SUMIF('Realisasi Hilirisasi'!$D:$D,Resume!$B11,'Realisasi Hilirisasi'!G:G)/1000000000 -> 0
B12: Pipe Bends | C12: =SUMIF('Realisasi Hilirisasi'!$D:$D,Resume!$B12,'Realisasi Hilirisasi'!E:E) -> 112 | D12: =SUMIF('Realisasi Hilirisasi'!$D:$D,Resume!$B12,'Realisasi Hilirisasi'!F:F)/1000000000 -> 8.7773616 | E12: =SUMIF('Realisasi Hilirisasi'!$D:$D,Resume!$B12,'Realisasi Hilirisasi'!G:G)/1000000000 -> 2.75485
B13: Seamless Pipe | C13: =SUMIF('Realisasi Hilirisasi'!$D:$D,Resume!$B13,'Realisasi Hilirisasi'!E:E) -> 11668.013 | D13: =SUMIF('Realisasi Hilirisasi'!$D:$D,Resume!$B13,'Realisasi Hilirisasi'!F:F)/1000000000 -> 132.14177 | E13: =SUMIF('Realisasi Hilirisasi'!$D:$D,Resume!$B13,'Realisasi Hilirisasi'!G:G)/1000000000 -> 12.18081
B14: Baja Ringan | C14: =SUMIF('Realisasi Hilirisasi'!$D:$D,Resume!$B14,'Realisasi Hilirisasi'!E:E) -> 3565.0796 | D14: =SUMIF('Realisasi Hilirisasi'!$D:$D,Resume!$B14,'Realisasi Hilirisasi'!F:F)/1000000000 -> 59.495083 | E14: =SUMIF('Realisasi Hilirisasi'!$D:$D,Resume!$B14,'Realisasi Hilirisasi'!G:G)/1000000000 -> 7.163185
B15: Floordeck | C15: =SUMIF('Realisasi Hilirisasi'!$D:$D,Resume!$B15,'Realisasi Hilirisasi'!E:E) -> 0 | D15: =SUMIF('Realisasi Hilirisasi'!$D:$D,Resume!$B15,'Realisasi Hilirisasi'!F:F)/1000000000 -> 0 | E15: =SUMIF('Realisasi Hilirisasi'!$D:$D,Resume!$B15,'Realisasi Hilirisasi'!G:G)/1000000000 -> 0
B16: Galvalum | C16: =SUMIF('Realisasi Hilirisasi'!$D:$D,Resume!$B16,'Realisasi Hilirisasi'!E:E) -> 0 | D16: =SUMIF('Realisasi Hilirisasi'!$D:$D,Resume!$B16,'Realisasi Hilirisasi'!F:F)/1000000000 -> 0 | E16: =SUMIF('Realisasi Hilirisasi'!$D:$D,Resume!$B16,'Realisasi Hilirisasi'!G:G)/1000000000 -> 0
... B20: Welded Beam & Custom Product | C20: =SUMIF('Realisasi Hilirisasi'!$D:$D,Resume!$B20,'Realisasi Hilirisasi'!E:E) -> 0 | D20: =SUMIF('Realisasi Hilirisasi'!$D:$D,Resume!$B20,'Realisasi Hilirisasi'!F:F)/1000000000 -> 0 | E20: =SUMIF('Realisasi Hilirisasi'!$D:$D,Resume!$B20,'Realisasi Hilirisasi'!G:G)/1000000000 -> 0
B22: TOTAL | C22: =SUM(C5:C21) -> 25402.839 | D22: =SUM(D5:D21) -> 377.19394 | E22: =SUM(E5:E21) -> 33.310672
B25: Entitas | C25: Qty (Ton) | D25: Revenue (Rp Milyar) | E25: Gross Profit (Rp Milyar)
B26: KBK | C26: =SUMIF('Realisasi Hilirisasi'!$C:$C,Resume!$B26,'Realisasi Hilirisasi'!E:E) -> 5428.2944 | D26: =SUMIF('Realisasi Hilirisasi'!$C:$C,Resume!$B26,'Realisasi Hilirisasi'!F:F)/1000000000 -> 106.86713 | E26: =SUMIF('Realisasi Hilirisasi'!$C:$C,Resume!$B26,'Realisasi Hilirisasi'!G:G)/1000000000 -> 3.2392711 | F26: =E26/C26 -> 0.0005967383 | G26: =D26-E26 -> 103.62785 | H26: =G26*1000 -> 103627.85
B27: KPI | C27: =SUMIF('Realisasi Hilirisasi'!$C:$C,Resume!$B27,'Realisasi Hilirisasi'!E:E) -> 14083.94 | D27: =SUMIF('Realisasi Hilirisasi'!$C:$C,Resume!$B27,'Realisasi Hilirisasi'!F:F)/1000000000 -> 182.22013 | E27: =SUMIF('Realisasi Hilirisasi'!$C:$C,Resume!$B27,'Realisasi Hilirisasi'!G:G)/1000000000 -> 16.189396 | F27: =E27/C27 -> 0.0011494934
B28: KNI | C28: =SUMIF('Realisasi Hilirisasi'!$C:$C,Resume!$B28,'Realisasi Hilirisasi'!E:E) -> 5890.6043 | D28: =SUMIF('Realisasi Hilirisasi'!$C:$C,Resume!$B28,'Realisasi Hilirisasi'!F:F)/1000000000 -> 88.10668 | E28: =SUMIF('Realisasi Hilirisasi'!$C:$C,Resume!$B28,'Realisasi Hilirisasi'!G:G)/1000000000 -> 13.882004 | F28: =E28/C28 -> 0.002356635
B29: KPdP | C29: =SUMIF('Realisasi Hilirisasi'!$C:$C,Resume!$B29,'Realisasi Hilirisasi'!E:E) -> 0 | D29: =SUMIF('Realisasi Hilirisasi'!$C:$C,Resume!$B29,'Realisasi Hilirisasi'!F:F)/1000000000 -> 0 | E29: =SUMIF('Realisasi Hilirisasi'!$C:$C,Resume!$B29,'Realisasi Hilirisasi'!G:G)/1000000000 -> 0
B31: TOTAL | C31: =SUM(C26:C30) -> 25402.839 | D31: =SUM(D26:D30) -> 377.19394 | E31: =SUM(E26:E30) -> 33.310672
B33: Entitas | C33: Qty (Ton) | D33: Target (Ton) | E33: Capaian (%)
B34: KBK | C34: =SUMIF('Realisasi Hilirisasi'!$C:$C,Resume!$B34,'Realisasi Hilirisasi'!E:E) -> 5428.2944 | D34: ='Per AP'!P10 -> 25000 | E34: =IF(C34=0,0,C34/D34) -> 0.21713178
B35: KPI | C35: =SUMIF('Realisasi Hilirisasi'!$C:$C,Resume!$B35,'Realisasi Hilirisasi'!E:E) -> 14083.94 | D35: ='Per AP'!P11 -> 6804 | E35: =IF(C35=0,0,C35/D35) -> 2.06995
B36: KNI | C36: =SUMIF('Realisasi Hilirisasi'!$C:$C,Resume!$B36,'Realisasi Hilirisasi'!E:E) -> 5890.6043 | D36: ='Per AP'!P12 -> 5000 | E36: =IF(C36=0,0,C36/D36) -> 1.1781209
B37: KPdP | C37: =SUMIF('Realisasi Hilirisasi'!$C:$C,Resume!$B37,'Realisasi Hilirisasi'!E:E) -> 0 | D37: ='Per AP'!P13 -> 0 | E37: =IF(C37=0,0,C37/D37) -> 0
B39: TOTAL | C39: =SUM(C34:C38) -> 25402.839 | D39: =SUM(D34:D38) -> 36804 | E39: =IF(C39=0,0,C39/D39) -> 0.69021951
C42: =344 -> 344
C43: =900 -> 900
C44: =C42+C43 -> 1244
C45: =C34-C44 -> 4184.2944

Sheet Per AP
P4: untuk diupdate
C6: 1 | D6: =C6+1 -> 2 | E6: =D6+1 -> 3 | F6: =E6+1 -> 4 | G6: =F6+1 -> 5 | H6: =G6+1 -> 6 | I6: =H6+1 -> 7 | J6: =I6+1 -> 8 | K6: =J6+1 -> 9 | ... N6: =M6+1 -> 12 | P6: 1
C7: JAN | D7: FEB | E7: MAR | F7: APR | G7: MEI | H7: JUNI | I7: JULI | J7: AGUTS | K7: SEPT | L7: OKT | M7: NOV | N7: DES | O7: AKUMULASI | P7: Target | Q7: Capaian | R7: Gap
B9: Qty (Ton)
B10: KBK | C10: ='Realisasi Hilirisasi'!S28 -> 143.32434 | D10: ='Realisasi Hilirisasi'!T28 -> 782.00073 | E10: ='Realisasi Hilirisasi'!U28 -> 681.34313 | F10: ='Realisasi Hilirisasi'!V28 -> 208.7867 | G10: ='Realisasi Hilirisasi'!W28 -> 592.8619 | H10: ='Realisasi Hilirisasi'!X28 -> -74.014673 | I10: ='Realisasi Hilirisasi'!Y28 -> 406.85827 | J10: ='Realisasi Hilirisasi'!Z28 -> 245.88916 | ... N10: ='Realisasi Hilirisasi'!AD28 -> 251.4456 | O10: =SUM(C10:N10) -> 5428.2944 | P10: ='Target Hilirisasi 2025'!AJ9 -> 25000 | Q10: =O10/P10 -> 0.21713178 | R10: =O10-P10 -> -19571.706
B11: KPI | C11: ='Realisasi Hilirisasi'!S29 -> 64 | D11: ='Realisasi Hilirisasi'!T29 -> 1293 | E11: ='Realisasi Hilirisasi'!U29 -> 366 | F11: ='Realisasi Hilirisasi'!V29 -> 80.334 | G11: ='Realisasi Hilirisasi'!W29 -> 1638.899 | H11: ='Realisasi Hilirisasi'!X29 -> 864.274 | I11: ='Realisasi Hilirisasi'!Y29 -> 300 | J11: ='Realisasi Hilirisasi'!Z29 -> 1340.533 | ... N11: ='Realisasi Hilirisasi'!AD29 -> 3953.021 | O11: =SUM(C11:N11) -> 14083.94 | P11: ='Target Hilirisasi 2025'!AJ10 -> 6804 | Q11: =O11/P11 -> 2.06995 | R11: =O11-P11 -> 7279.94
B12: KNI | C12: ='Realisasi Hilirisasi'!S30 -> 344.54045 | D12: ='Realisasi Hilirisasi'!T30 -> 348.05116 | E12: ='Realisasi Hilirisasi'!U30 -> 367.04059 | F12: ='Realisasi Hilirisasi'!V30 -> 186.94335 | G12: ='Realisasi Hilirisasi'!W30 -> 256.8991 | H12: ='Realisasi Hilirisasi'!X30 -> 246.90429 | I12: ='Realisasi Hilirisasi'!Y30 -> 435.0839 | J12: ='Realisasi Hilirisasi'!Z30 -> 659.639 | ... N12: ='Realisasi Hilirisasi'!AD30 -> 287.77385 | O12: =SUM(C12:N12) -> 5890.6043 | P12: ='Target Hilirisasi 2025'!AJ11 -> 5000 | Q12: =O12/P12 -> 1.1781209 | R12: =O12-P12 -> 890.60429
B13: KPdP | C13: ='Realisasi Hilirisasi'!S31 -> 0 | D13: ='Realisasi Hilirisasi'!T31 -> 0 | E13: ='Realisasi Hilirisasi'!U31 -> 0 | F13: ='Realisasi Hilirisasi'!V31 -> 0 | G13: ='Realisasi Hilirisasi'!W31 -> 0 | H13: ='Realisasi Hilirisasi'!X31 -> 0 | I13: ='Realisasi Hilirisasi'!Y31 -> 0 | J13: ='Realisasi Hilirisasi'!Z31 -> 0 | ... N13: ='Realisasi Hilirisasi'!AD31 -> 0 | O13: =SUM(C13:N13) -> 0 | P13: ='Target Hilirisasi 2025'!AJ12 -> 0 | Q13: =O13/P13 -> #DIV/0! | R13: =O13-P13 -> 0
B14: Total | C14: =SUM(C10:C13) -> 551.86479 | D14: =SUM(D10:D13) -> 2423.0519 | E14: =SUM(E10:E13) -> 1414.3837 | F14: =SUM(F10:F13) -> 476.06405 | G14: =SUM(G10:G13) -> 2488.66 | H14: =SUM(H10:H13) -> 1037.1636 | I14: =SUM(I10:I13) -> 1141.9422 | J14: =SUM(J10:J13) -> 2246.0612 | ... P14: =SUM(P10:P13) -> 36804 | Q14: =O14/P14 -> 0.69021951 | R14: =SUM(R10:R13) -> -11401.161
B16: Revenue (Rp Juta)
B17: KBK | C17: =SUMIFS('Realisasi Hilirisasi'!$F:$F,'Realisasi Hilirisasi'!$C:$C,'Per AP'!$B17,'Realisasi Hilirisasi'!$B:$B,'Per AP'!C$6)/1000000 -> 3321.6862 | D17: =SUMIFS('Realisasi Hilirisasi'!$F:$F,'Realisasi Hilirisasi'!$C:$C,'Per AP'!$B17,'Realisasi Hilirisasi'!$B:$B,'Per AP'!D$6)/1000000 -> 15508.642 | E17: =SUMIFS('Realisasi Hilirisasi'!$F:$F,'Realisasi Hilirisasi'!$C:$C,'Per AP'!$B17,'Realisasi Hilirisasi'!$B:$B,'Per AP'!E$6)/1000000 -> 6813.0539 | F17: =SUMIFS('Realisasi Hilirisasi'!$F:$F,'Realisasi Hilirisasi'!$C:$C,'Per AP'!$B17,'Realisasi Hilirisasi'!$B:$B,'Per AP'!F$6)/1000000 -> 6293.6976 | G17: =SUMIFS('Realisasi Hilirisasi'!$F:$F,'Realisasi Hilirisasi'!$C:$C,'Per AP'!$B17,'Realisasi Hilirisasi'!$B:$B,'Per AP'!G$6)/1000000 -> 12374.35 | H17: =SUMIFS('Realisasi Hilirisasi'!$F:$F,'Realisasi Hilirisasi'!$C:$C,'Per AP'!$B17,'Realisasi Hilirisasi'!$B:$B,'Per AP'!H$6)/1000000 -> -2245.0901 | I17: =SUMIFS('Realisasi Hilirisasi'!$F:$F,'Realisasi Hilirisasi'!$C:$C,'Per AP'!$B17,'Realisasi Hilirisasi'!$B:$B,'Per AP'!I$6)/1000000 -> 7393.4319 | J17: =SUMIFS('Realisasi Hilirisasi'!$F:$F,'Realisasi Hilirisasi'!$C:$C,'Per AP'!$B17,'Realisasi Hilirisasi'!$B:$B,'Per AP'!J$6)/1000000 -> 5259.7025 | ... N17: =SUMIFS('Realisasi Hilirisasi'!$F:$F,'Realisasi Hilirisasi'!$C:$C,'Per AP'!$B17,'Realisasi Hilirisasi'!$B:$B,'Per AP'!N$6)/1000000 -> 7320.8347 | O17: =SUM(C17:N17) -> 106867.13 | P17: =P10*18000*1000/1000000 -> 450000 | Q17: =O17/P17 -> 0.2374825
B18: KPI | C18: =SUMIFS('Realisasi Hilirisasi'!$F:$F,'Realisasi Hilirisasi'!$C:$C,'Per AP'!$B18,'Realisasi Hilirisasi'!$B:$B,'Per AP'!C$6)/1000000 -> 979.03913 | D18: =SUMIFS('Realisasi Hilirisasi'!$F:$F,'Realisasi Hilirisasi'!$C:$C,'Per AP'!$B18,'Realisasi Hilirisasi'!$B:$B,'Per AP'!D$6)/1000000 -> 25344.148 | E18: =SUMIFS('Realisasi Hilirisasi'!$F:$F,'Realisasi Hilirisasi'!$C:$C,'Per AP'!$B18,'Realisasi Hilirisasi'!$B:$B,'Per AP'!E$6)/1000000 -> 6906.9412 | F18: =SUMIFS('Realisasi Hilirisasi'!$F:$F,'Realisasi Hilirisasi'!$C:$C,'Per AP'!$B18,'Realisasi Hilirisasi'!$B:$B,'Per AP'!F$6)/1000000 -> 1414.1512 | G18: =SUMIFS('Realisasi Hilirisasi'!$F:$F,'Realisasi Hilirisasi'!$C:$C,'Per AP'!$B18,'Realisasi Hilirisasi'!$B:$B,'Per AP'!G$6)/1000000 -> 21385.991 | H18: =SUMIFS('Realisasi Hilirisasi'!$F:$F,'Realisasi Hilirisasi'!$C:$C,'Per AP'!$B18,'Realisasi Hilirisasi'!$B:$B,'Per AP'!H$6)/1000000 -> 11835.535 | I18: =SUMIFS('Realisasi Hilirisasi'!$F:$F,'Realisasi Hilirisasi'!$C:$C,'Per AP'!$B18,'Realisasi Hilirisasi'!$B:$B,'Per AP'!I$6)/1000000 -> 5372.8115 | J18: =SUMIFS('Realisasi Hilirisasi'!$F:$F,'Realisasi Hilirisasi'!$C:$C,'Per AP'!$B18,'Realisasi Hilirisasi'!$B:$B,'Per AP'!J$6)/1000000 -> 16421.458 | ... N18: =SUMIFS('Realisasi Hilirisasi'!$F:$F,'Realisasi Hilirisasi'!$C:$C,'Per AP'!$B18,'Realisasi Hilirisasi'!$B:$B,'Per AP'!N$6)/1000000 -> 44833.448 | O18: =SUM(C18:N18) -> 182220.13 | P18: =P11*15000*1000/1000000 -> 102060 | Q18: =O18/P18 -> 1.7854216
B19: KNI | C19: =SUMIFS('Realisasi Hilirisasi'!$F:$F,'Realisasi Hilirisasi'!$C:$C,'Per AP'!$B19,'Realisasi Hilirisasi'!$B:$B,'Per AP'!C$6)/1000000 -> 5478.4215 | D19: =SUMIFS('Realisasi Hilirisasi'!$F:$F,'Realisasi Hilirisasi'!$C:$C,'Per AP'!$B19,'Realisasi Hilirisasi'!$B:$B,'Per AP'!D$6)/1000000 -> 5643.7765 | E19: =SUMIFS('Realisasi Hilirisasi'!$F:$F,'Realisasi Hilirisasi'!$C:$C,'Per AP'!$B19,'Realisasi Hilirisasi'!$B:$B,'Per AP'!E$6)/1000000 -> 6029.2026 | F19: =SUMIFS('Realisasi Hilirisasi'!$F:$F,'Realisasi Hilirisasi'!$C:$C,'Per AP'!$B19,'Realisasi Hilirisasi'!$B:$B,'Per AP'!F$6)/1000000 -> 3162.5705 | G19: =SUMIFS('Realisasi Hilirisasi'!$F:$F,'Realisasi Hilirisasi'!$C:$C,'Per AP'!$B19,'Realisasi Hilirisasi'!$B:$B,'Per AP'!G$6)/1000000 -> 4249.1732 | H19: =SUMIFS('Realisasi Hilirisasi'!$F:$F,'Realisasi Hilirisasi'!$C:$C,'Per AP'!$B19,'Realisasi Hilirisasi'!$B:$B,'Per AP'!H$6)/1000000 -> 4106.6498 | I19: =SUMIFS('Realisasi Hilirisasi'!$F:$F,'Realisasi Hilirisasi'!$C:$C,'Per AP'!$B19,'Realisasi Hilirisasi'!$B:$B,'Per AP'!I$6)/1000000 -> 6973.6683 | J19: =SUMIFS('Realisasi Hilirisasi'!$F:$F,'Realisasi Hilirisasi'!$C:$C,'Per AP'!$B19,'Realisasi Hilirisasi'!$B:$B,'Per AP'!J$6)/1000000 -> 10178.364 | ... N19: =SUMIFS('Realisasi Hilirisasi'!$F:$F,'Realisasi Hilirisasi'!$C:$C,'Per AP'!$B19,'Realisasi Hilirisasi'!$B:$B,'Per AP'!N$6)/1000000 -> 4858.2584 | O19: =SUM(C19:N19) -> 88106.68 | P19: =P12*15000*1000/1000000 -> 75000 | Q19: =O19/P19 -> 1.1747557
B20: KPdP | C20: =SUMIFS('Realisasi Hilirisasi'!$F:$F,'Realisasi Hilirisasi'!$C:$C,'Per AP'!$B20,'Realisasi Hilirisasi'!$B:$B,'Per AP'!C$6)/1000000 -> 0 | D20: =SUMIFS('Realisasi Hilirisasi'!$F:$F,'Realisasi Hilirisasi'!$C:$C,'Per AP'!$B20,'Realisasi Hilirisasi'!$B:$B,'Per AP'!D$6)/1000000 -> 0 | E20: =SUMIFS('Realisasi Hilirisasi'!$F:$F,'Realisasi Hilirisasi'!$C:$C,'Per AP'!$B20,'Realisasi Hilirisasi'!$B:$B,'Per AP'!E$6)/1000000 -> 0 | F20: =SUMIFS('Realisasi Hilirisasi'!$F:$F,'Realisasi Hilirisasi'!$C:$C,'Per AP'!$B20,'Realisasi Hilirisasi'!$B:$B,'Per AP'!F$6)/1000000 -> 0 | G20: =SUMIFS('Realisasi Hilirisasi'!$F:$F,'Realisasi Hilirisasi'!$C:$C,'Per AP'!$B20,'Realisasi Hilirisasi'!$B:$B,'Per AP'!G$6)/1000000 -> 0 | H20: =SUMIFS('Realisasi Hilirisasi'!$F:$F,'Realisasi Hilirisasi'!$C:$C,'Per AP'!$B20,'Realisasi Hilirisasi'!$B:$B,'Per AP'!H$6)/1000000 -> 0 | I20: =SUMIFS('Realisasi Hilirisasi'!$F:$F,'Realisasi Hilirisasi'!$C:$C,'Per AP'!$B20,'Realisasi Hilirisasi'!$B:$B,'Per AP'!I$6)/1000000 -> 0 | J20: =SUMIFS('Realisasi Hilirisasi'!$F:$F,'Realisasi Hilirisasi'!$C:$C,'Per AP'!$B20,'Realisasi Hilirisasi'!$B:$B,'Per AP'!J$6)/1000000 -> 0 | ... N20: =SUMIFS('Realisasi Hilirisasi'!$F:$F,'Realisasi Hilirisasi'!$C:$C,'Per AP'!$B20,'Realisasi Hilirisasi'!$B:$B,'Per AP'!N$6)/1000000 -> 0 | O20: =SUM(C20:N20) -> 0 | P20: =P13*18500000/1000000 -> 0 | Q20: =O20/P20 -> #DIV/0!
B21: Total | C21: =SUM(C17:C20) -> 9779.1468 | D21: =SUM(D17:D20) -> 46496.566 | E21: =SUM(E17:E20) -> 19749.198 | F21: =SUM(F17:F20) -> 10870.419 | G21: =SUM(G17:G20) -> 38009.515 | H21: =SUM(H17:H20) -> 13697.094 | I21: =SUM(I17:I20) -> 19739.912 | J21: =SUM(J17:J20) -> 31859.524 | ... P21: =SUM(P17:P20) -> 627060 | Q21: =O21/P21 -> 0.60152767
B23: Gross Profit (Rp Juta)
B24: KBK | C24: =SUMIFS('Realisasi Hilirisasi'!$G:$G,'Realisasi Hilirisasi'!$C:$C,'Per AP'!$B24,'Realisasi Hilirisasi'!$B:$B,'Per AP'!C$6)/1000000 -> 263.19288 | D24: =SUMIFS('Realisasi Hilirisasi'!$G:$G,'Realisasi Hilirisasi'!$C:$C,'Per AP'!$B24,'Realisasi Hilirisasi'!$B:$B,'Per AP'!D$6)/1000000 -> 974.19603 | E24: =SUMIFS('Realisasi Hilirisasi'!$G:$G,'Realisasi Hilirisasi'!$C:$C,'Per AP'!$B24,'Realisasi Hilirisasi'!$B:$B,'Per AP'!E$6)/1000000 -> 668.34521 | F24: =SUMIFS('Realisasi Hilirisasi'!$G:$G,'Realisasi Hilirisasi'!$C:$C,'Per AP'!$B24,'Realisasi Hilirisasi'!$B:$B,'Per AP'!F$6)/1000000 -> 530.48556 | G24: =SUMIFS('Realisasi Hilirisasi'!$G:$G,'Realisasi Hilirisasi'!$C:$C,'Per AP'!$B24,'Realisasi Hilirisasi'!$B:$B,'Per AP'!G$6)/1000000 -> 673.12159 | H24: =SUMIFS('Realisasi Hilirisasi'!$G:$G,'Realisasi Hilirisasi'!$C:$C,'Per AP'!$B24,'Realisasi Hilirisasi'!$B:$B,'Per AP'!H$6)/1000000 -> -27.403243 | I24: =SUMIFS('Realisasi Hilirisasi'!$G:$G,'Realisasi Hilirisasi'!$C:$C,'Per AP'!$B24,'Realisasi Hilirisasi'!$B:$B,'Per AP'!I$6)/1000000 -> -270.9795 | J24: =SUMIFS('Realisasi Hilirisasi'!$G:$G,'Realisasi Hilirisasi'!$C:$C,'Per AP'!$B24,'Realisasi Hilirisasi'!$B:$B,'Per AP'!J$6)/1000000 -> -595.86814 | ... N24: =SUMIFS('Realisasi Hilirisasi'!$G:$G,'Realisasi Hilirisasi'!$C:$C,'Per AP'!$B24,'Realisasi Hilirisasi'!$B:$B,'Per AP'!N$6)/1000000 -> 468.83878 | O24: =SUM(C24:N24) -> 3239.2711 | P24: =P17*5% -> 22500 | Q24: =O24/P24 -> 0.14396761
B25: KPI | C25: =SUMIFS('Realisasi Hilirisasi'!$G:$G,'Realisasi Hilirisasi'!$C:$C,'Per AP'!$B25,'Realisasi Hilirisasi'!$B:$B,'Per AP'!C$6)/1000000 -> 15.8613 | D25: =SUMIFS('Realisasi Hilirisasi'!$G:$G,'Realisasi Hilirisasi'!$C:$C,'Per AP'!$B25,'Realisasi Hilirisasi'!$B:$B,'Per AP'!D$6)/1000000 -> 5685.1532 | E25: =SUMIFS('Realisasi Hilirisasi'!$G:$G,'Realisasi Hilirisasi'!$C:$C,'Per AP'!$B25,'Realisasi Hilirisasi'!$B:$B,'Per AP'!E$6)/1000000 -> 91.035894 | F25: =SUMIFS('Realisasi Hilirisasi'!$G:$G,'Realisasi Hilirisasi'!$C:$C,'Per AP'!$B25,'Realisasi Hilirisasi'!$B:$B,'Per AP'!F$6)/1000000 -> 20.003166 | G25: =SUMIFS('Realisasi Hilirisasi'!$G:$G,'Realisasi Hilirisasi'!$C:$C,'Per AP'!$B25,'Realisasi Hilirisasi'!$B:$B,'Per AP'!G$6)/1000000 -> 2630.4417 | H25: =SUMIFS('Realisasi Hilirisasi'!$G:$G,'Realisasi Hilirisasi'!$C:$C,'Per AP'!$B25,'Realisasi Hilirisasi'!$B:$B,'Per AP'!H$6)/1000000 -> 290.92046 | I25: =SUMIFS('Realisasi Hilirisasi'!$G:$G,'Realisasi Hilirisasi'!$C:$C,'Per AP'!$B25,'Realisasi Hilirisasi'!$B:$B,'Per AP'!I$6)/1000000 -> 74.7 | J25: =SUMIFS('Realisasi Hilirisasi'!$G:$G,'Realisasi Hilirisasi'!$C:$C,'Per AP'!$B25,'Realisasi Hilirisasi'!$B:$B,'Per AP'!J$6)/1000000 -> 1290.1712 | ... N25: =SUMIFS('Realisasi Hilirisasi'!$G:$G,'Realisasi Hilirisasi'!$C:$C,'Per AP'!$B25,'Realisasi Hilirisasi'!$B:$B,'Per AP'!N$6)/1000000 -> 3333.857 | O25: =SUM(C25:N25) -> 16189.396 | P25: =P18*5% -> 5103 | Q25: =O25/P25 -> 3.1725252
B26: KNI | C26: =SUMIFS('Realisasi Hilirisasi'!$G:$G,'Realisasi Hilirisasi'!$C:$C,'Per AP'!$B26,'Realisasi Hilirisasi'!$B:$B,'Per AP'!C$6)/1000000 -> 118.66562 | D26: =SUMIFS('Realisasi Hilirisasi'!$G:$G,'Realisasi Hilirisasi'!$C:$C,'Per AP'!$B26,'Realisasi Hilirisasi'!$B:$B,'Per AP'!D$6)/1000000 -> 254.41068 | E26: =SUMIFS('Realisasi Hilirisasi'!$G:$G,'Realisasi Hilirisasi'!$C:$C,'Per AP'!$B26,'Realisasi Hilirisasi'!$B:$B,'Per AP'!E$6)/1000000 -> 237.49319 | F26: =SUMIFS('Realisasi Hilirisasi'!$G:$G,'Realisasi Hilirisasi'!$C:$C,'Per AP'!$B26,'Realisasi Hilirisasi'!$B:$B,'Per AP'!F$6)/1000000 -> 43.065182 | G26: =SUMIFS('Realisasi Hilirisasi'!$G:$G,'Realisasi Hilirisasi'!$C:$C,'Per AP'!$B26,'Realisasi Hilirisasi'!$B:$B,'Per AP'!G$6)/1000000 -> 62.795663 | H26: =SUMIFS('Realisasi Hilirisasi'!$G:$G,'Realisasi Hilirisasi'!$C:$C,'Per AP'!$B26,'Realisasi Hilirisasi'!$B:$B,'Per AP'!H$6)/1000000 -> 60.689406 | I26: =SUMIFS('Realisasi Hilirisasi'!$G:$G,'Realisasi Hilirisasi'!$C:$C,'Per AP'!$B26,'Realisasi Hilirisasi'!$B:$B,'Per AP'!I$6)/1000000 -> 122.29356 | J26: =SUMIFS('Realisasi Hilirisasi'!$G:$G,'Realisasi Hilirisasi'!$C:$C,'Per AP'!$B26,'Realisasi Hilirisasi'!$B:$B,'Per AP'!J$6)/1000000 -> 9973.9998 | ... N26: =SUMIFS('Realisasi Hilirisasi'!$G:$G,'Realisasi Hilirisasi'!$C:$C,'Per AP'!$B26,'Realisasi Hilirisasi'!$B:$B,'Per AP'!N$6)/1000000 -> 81.854833 | O26: =SUM(C26:N26) -> 13882.004 | P26: =P19*3% -> 2250 | Q26: =O26/P26 -> 6.1697797
B27: KPdP | C27: =SUMIFS('Realisasi Hilirisasi'!$G:$G,'Realisasi Hilirisasi'!$C:$C,'Per AP'!$B27,'Realisasi Hilirisasi'!$B:$B,'Per AP'!C$6)/1000000 -> 0 | D27: =SUMIFS('Realisasi Hilirisasi'!$G:$G,'Realisasi Hilirisasi'!$C:$C,'Per AP'!$B27,'Realisasi Hilirisasi'!$B:$B,'Per AP'!D$6)/1000000 -> 0 | E27: =SUMIFS('Realisasi Hilirisasi'!$G:$G,'Realisasi Hilirisasi'!$C:$C,'Per AP'!$B27,'Realisasi Hilirisasi'!$B:$B,'Per AP'!E$6)/1000000 -> 0 | F27: =SUMIFS('Realisasi Hilirisasi'!$G:$G,'Realisasi Hilirisasi'!$C:$C,'Per AP'!$B27,'Realisasi Hilirisasi'!$B:$B,'Per AP'!F$6)/1000000 -> 0 | G27: =SUMIFS('Realisasi Hilirisasi'!$G:$G,'Realisasi Hilirisasi'!$C:$C,'Per AP'!$B27,'Realisasi Hilirisasi'!$B:$B,'Per AP'!G$6)/1000000 -> 0 | H27: =SUMIFS('Realisasi Hilirisasi'!$G:$G,'Realisasi Hilirisasi'!$C:$C,'Per AP'!$B27,'Realisasi Hilirisasi'!$B:$B,'Per AP'!H$6)/1000000 -> 0 | I27: =SUMIFS('Realisasi Hilirisasi'!$G:$G,'Realisasi Hilirisasi'!$C:$C,'Per AP'!$B27,'Realisasi Hilirisasi'!$B:$B,'Per AP'!I$6)/1000000 -> 0 | J27: =SUMIFS('Realisasi Hilirisasi'!$G:$G,'Realisasi Hilirisasi'!$C:$C,'Per AP'!$B27,'Realisasi Hilirisasi'!$B:$B,'Per AP'!J$6)/1000000 -> 0 | ... N27: =SUMIFS('Realisasi Hilirisasi'!$G:$G,'Realisasi Hilirisasi'!$C:$C,'Per AP'!$B27,'Realisasi Hilirisasi'!$B:$B,'Per AP'!N$6)/1000000 -> 0 | O27: =SUM(C27:N27) -> 0 | P27: =P20*4% -> 0 | Q27: =O27/P27 -> #DIV/0!
B28: Total | C28: =SUM(C24:C27) -> 397.7198 | D28: =SUM(D24:D27) -> 6913.7599 | E28: =SUM(E24:E27) -> 996.8743 | F28: =SUM(F24:F27) -> 593.55391 | G28: =SUM(G24:G27) -> 3366.359 | H28: =SUM(H24:H27) -> 324.20662 | I28: =SUM(I24:I27) -> -73.985932 | J28: =SUM(J24:J27) -> 10668.303 | ... P28: =SUM(P24:P27) -> 29853 | Q28: =O28/P28 -> 1.1158233
B30: Gross Margin (%)
B31: KBK | C31: =IF(C10=0,0,C24/C17) -> 0.07923472 | D31: =IF(D10=0,0,D24/D17) -> 0.062816332 | E31: =IF(E10=0,0,E24/E17) -> 0.098097743 | F31: =IF(F10=0,0,F24/F17) -> 0.084288378 | G31: =IF(G10=0,0,G24/G17) -> 0.054396519 | H31: =IF(H10=0,0,H24/H17) -> 0.012205855 | I31: =IF(I10=0,0,I24/I17) -> -0.036651382 | J31: =IF(J10=0,0,J24/J17) -> -0.11328932 | ... O31: =IF(O10=0,0,O24/O17) -> 0.030311203 | P31: =P24/P17 -> 0.05 | Q31: =O31/P31 -> 0.60622406
B32: KPI | C32: =IF(C11=0,0,C25/C18) -> 0.016200885 | D32: =IF(D11=0,0,D25/D18) -> 0.22431818 | E32: =IF(E11=0,0,E25/E18) -> 0.013180349 | F32: =IF(F11=0,0,F25/F18) -> 0.014144998 | G32: =IF(G11=0,0,G25/G18) -> 0.12299835 | H32: =IF(H11=0,0,H25/H18) -> 0.024580255 | I32: =IF(I11=0,0,I25/I18) -> 0.013903335 | J32: =IF(J11=0,0,J25/J18) -> 0.078566175 | ... O32: =IF(O11=0,0,O25/O18) -> 0.088845266 | P32: =P25/P18 -> 0.05 | Q32: =O32/P32 -> 1.7769053
B33: KNI | C33: =IF(C12=0,0,C26/C19) -> 0.02166055 | D33: =IF(D12=0,0,D26/D19) -> 0.045078093 | E33: =IF(E12=0,0,E26/E19) -> 0.039390481 | F33: =IF(F12=0,0,F26/F19) -> 0.013617146 | G33: =IF(G12=0,0,G26/G19) -> 0.014778325 | H33: =IF(H12=0,0,H26/H19) -> 0.014778325 | I33: =IF(I12=0,0,I26/I19) -> 0.017536476 | J33: =IF(J12=0,0,J26/J19) -> 0.97992174 | ... O33: =IF(O12=0,0,O26/O19) -> 0.15755904 | P33: =P26/P19 -> 0.03 | Q33: =O33/P33 -> 5.2519681
B34: KPdP | C34: =IF(C13=0,0,C27/C20) -> 0 | D34: =IF(D13=0,0,D27/D20) -> 0 | E34: =IF(E13=0,0,E27/E20) -> 0 | F34: =IF(F13=0,0,F27/F20) -> 0 | G34: =IF(G13=0,0,G27/G20) -> 0 | H34: =IF(H13=0,0,H27/H20) -> 0 | I34: =IF(I13=0,0,I27/I20) -> 0 | J34: =IF(J13=0,0,J27/J20) -> 0 | ... O34: =IF(O13=0,0,O27/O20) -> 0 | P34: =P27/P20 -> #DIV/0! | Q34: =O34/P34 -> #DIV/0!
B35: Total | C35: =IF(C14=0,0,C28/C21) -> 0.040670194 | D35: =IF(D14=0,0,D28/D21) -> 0.14869399 | E35: =IF(E14=0,0,E28/E21) -> 0.050476698 | F35: =IF(F14=0,0,F28/F21) -> 0.054602669 | G35: =IF(G14=0,0,G28/G21) -> 0.088566218 | H35: =IF(H14=0,0,H28/H21) -> 0.023669737 | I35: =IF(I14=0,0,I28/I21) -> -0.0037480376 | J35: =IF(J14=0,0,J28/J21) -> 0.33485443 | ... O35: =IF(O14=0,0,O28/O21) -> 0.088311789 | P35: =P28/P21 -> 0.047607884 | Q35: =O35/P35 -> 1.8549824

Sheet Target Hilirisasi 2025
B2: PT KRAKATAU BAJA KONSTRUKSI
B4: TARGET VOLUME STEEL BASED PRODUCT 2025
Y5: 1 | Z5: =Y5+1 -> 2 | AA5: =Z5+1 -> 3 | AB5: =AA5+1 -> 4 | AC5: =AB5+1 -> 5 | AD5: =AC5+1 -> 6 | AE5: =AD5+1 -> 7 | AF5: =AE5+1 -> 8 | AG5: =AF5+1 -> 9 | ... AJ5: =AI5+1 -> 12
B7: ORIGINAL TARGET | E7: 45658 | F7: =E7+31 -> 45689 | G7: =F7+31 -> 45720 | H7: =G7+31 -> 45751 | I7: =H7+31 -> 45782 | J7: =I7+31 -> 45813 | K7: =J7+31 -> 45844 | L7: =K7+31 -> 45875 | M7: =L7+31 -> 45906 | ... P7: =O7+31 -> 45999 | Q7: TOTAL | R7: REALISASI 2023 | S7: REALISASI 2022 | T7: Vs 2023 | Y7: 45658 | Z7: =Y7+31 -> 45689 | AA7: =Z7+31 -> 45720 | AB7: =AA7+31 -> 45751 | AC7: =AB7+31 -> 45782 | AD7: =AC7+31 -> 45813 | AE7: =AD7+31 -> 45844 | AF7: =AE7+31 -> 45875 | AG7: =AF7+31 -> 45906 | ... AJ7: =AI7+31 -> 45999
B9: KBK Induk | D9: Ton | E9: 2200 | F9: 2225 | G9: 1125 | H9: 1200 | I9: 1700 | J9: 2350 | K9: 2475 | L9: 2500 | M9: 2500 | N9: 2500 | O9: 2500 | P9: 1725 | Q9: =SUM(E9:P9) -> 25000 | R9: 9926.3788 | S9: ='Per AP#2'!U19 -> 18157 | T9: =Q9/R9 -> 2.5185418 | Y9: =E9 -> 2200 | Z9: =Y9+F9 -> 4425 | AA9: =Z9+G9 -> 5550 | AB9: =AA9+H9 -> 6750 | AC9: =AB9+I9 -> 8450 | AD9: =AC9+J9 -> 10800 | AE9: =AD9+K9 -> 13275 | AF9: =AE9+L9 -> 15775 | AG9: =AF9+M9 -> 18275 | ... AJ9: =AI9+P9 -> 25000
B10: KPI | D10: Ton | E10: 378 | F10: 630 | G10: 630 | H10: 630 | I10: 378 | J10: 630 | K10: 630 | L10: 630 | M10: 630 | N10: 630 | O10: 630 | P10: 378 | Q10: =SUM(E10:P10) -> 6804 | R10: 4725.485 | S10: ='Per AP#2'!U20 -> 1617 | T10: =Q10/R10 -> 1.4398522 | V10: =Q10/R10 -> 1.4398522 | Y10: =E10 -> 378 | Z10: =Y10+F10 -> 1008 | AA10: =Z10+G10 -> 1638 | AB10: =AA10+H10 -> 2268 | AC10: =AB10+I10 -> 2646 | AD10: =AC10+J10 -> 3276 | AE10: =AD10+K10 -> 3906 | AF10: =AE10+L10 -> 4536 | AG10: =AF10+M10 -> 5166 | ... AJ10: =AI10+P10 -> 6804
B11: KNI | D11: Ton | E11: 400 | F11: 400 | G11: 300 | H11: 200 | I11: 500 | J11: 500 | K11: 500 | L11: 500 | M11: 500 | N11: 500 | O11: 500 | P11: 200 | Q11: =SUM(E11:P11) -> 5000 | R11: 7412.5587 | S11: ='Per AP#2'!U21 -> 5200 | T11: =Q11/R11 -> 0.67453092 | Y11: =E11 -> 400 | Z11: =Y11+F11 -> 800 | AA11: =Z11+G11 -> 1100 | AB11: =AA11+H11 -> 1300 | AC11: =AB11+I11 -> 1800 | AD11: =AC11+J11 -> 2300 | AE11: =AD11+K11 -> 2800 | AF11: =AE11+L11 -> 3300 | AG11: =AF11+M11 -> 3800 | ... AJ11: =AI11+P11 -> 5000
B12: KPdP | D12: Ton | E12: 0 | F12: 0 | G12: 0 | H12: 0 | I12: 0 | J12: 0 | K12: 0 | L12: 0 | M12: 0 | N12: 0 | O12: 0 | P12: 0 | Q12: =SUM(E12:P12) -> 0 | R12: 3565.8 | S12: ='Per AP#2'!U22 -> 2757 | T12: =Q12/R12 -> 0 | Y12: =E12 -> 0 | Z12: =Y12+F12 -> 0 | AA12: =Z12+G12 -> 0 | AB12: =AA12+H12 -> 0 | AC12: =AB12+I12 -> 0 | AD12: =AC12+J12 -> 0 | AE12: =AD12+K12 -> 0 | AF12: =AE12+L12 -> 0 | AG12: =AF12+M12 -> 0 | ... AJ12: =AI12+P12 -> 0
B14: Total KBK&Grup | D14: Ton | E14: =SUM(E9:E13) -> 2978 | F14: =SUM(F9:F13) -> 3255 | G14: =SUM(G9:G13) -> 2055 | H14: =SUM(H9:H13) -> 2030 | I14: =SUM(I9:I13) -> 2578 | J14: =SUM(J9:J13) -> 3480 | K14: =SUM(K9:K13) -> 3605 | L14: =SUM(L9:L13) -> 3630 | ... S14: =SUM(S9:S13) -> 27731 | T14: =Q14/R14 -> 1.435961 | Y14: =SUM(Y9:Y13) -> 2978 | Z14: =SUM(Z9:Z13) -> 6233 | AA14: =SUM(AA9:AA13) -> 8288 | AB14: =SUM(AB9:AB13) -> 10318 | AC14: =SUM(AC9:AC13) -> 12896 | AD14: =SUM(AD9:AD13) -> 16376 | AE14: =SUM(AE9:AE13) -> 19981 | AF14: =SUM(AF9:AF13) -> 23611 | ... AJ14: =SUM(AJ9:AJ13) -> 36804
B16: Tobe Discussed
B17: INTERNAL/STRETCH TARGET | E17: 45292 | F17: =E17+31 -> 45323 | G17: =F17+31 -> 45354 | H17: =G17+31 -> 45385 | I17: =H17+31 -> 45416 | J17: =I17+31 -> 45447 | K17: =J17+31 -> 45478 | L17: =K17+31 -> 45509 | M17: =L17+31 -> 45540 | ... P17: =O17+31 -> 45633 | Q17: TOTAL | R17: REALISASI 2023 | S17: REALISASI 2022 | T17: Vs 2023
B19: KBK Induk | D19: Ton | E19: =E9 -> 2200 | F19: =F9 -> 2225 | G19: =G9 -> 1125 | H19: =H9 -> 1200 | I19: =I9 -> 1700 | J19: =J9 -> 2350 | K19: =K9 -> 2475 | L19: =L9 -> 2500 | ... P19: =P9 -> 1725 | Q19: =SUM(E19:P19) -> 25000 | R19: =R9 -> 9926.3788 | S19: =S9 -> 18157 | T19: =Q19/R19 -> 2.5185418 | V19: =Q19 -> 25000
B20: KPI | D20: Ton | E20: =E10 -> 378 | F20: =F10 -> 630 | G20: =G10 -> 630 | H20: =H10 -> 630 | I20: =I10 -> 378 | J20: =J10 -> 630 | K20: =K10 -> 630 | L20: =L10 -> 630 | ... P20: =P10 -> 378 | Q20: =SUM(E20:P20) -> 6804 | R20: =R10 -> 4725.485 | S20: =S10 -> 1617 | T20: =Q20/R20 -> 1.4398522 | V20: =CEILING(R20*1.15,50) -> 5450 | X20: =V20/Q10 -> 0.80099941
B21: KNI | D21: Ton | E21: 750 | F21: 750 | G21: 750 | H21: 500 | I21: 750 | J21: 750 | K21: 750 | L21: 750 | M21: 750 | N21: 750 | O21: 750 | P21: 500 | Q21: =SUM(E21:P21) -> 8500 | R21: =R11 -> 7412.5587 | S21: =S11 -> 5200 | T21: =Q21/R21 -> 1.1467026 | V21: =Q21 -> 8500
B22: KPdP | D22: Ton | E22: =E12 -> 0 | F22: =F12 -> 0 | G22: =G12 -> 0 | H22: =H12 -> 0 | I22: =I12 -> 0 | J22: =J12 -> 0 | K22: 325 | L22: 325 | M22: 325 | N22: 325 | O22: 325 | P22: =P12 -> 0 | Q22: =SUM(E22:P22) -> 1625 | R22: =R12 -> 3565.8 | S22: =S12 -> 2757 | T22: =Q22/R22 -> 0.45571821 | V22: =Q22 -> 1625
B24: Total KBK&Grup | D24: Ton | E24: =SUM(E19:E23) -> 3328 | F24: =SUM(F19:F23) -> 3605 | G24: =SUM(G19:G23) -> 2505 | H24: =SUM(H19:H23) -> 2330 | I24: =SUM(I19:I23) -> 2828 | J24: =SUM(J19:J23) -> 3730 | K24: =SUM(K19:K23) -> 4180 | L24: =SUM(L19:L23) -> 4205 | ... S24: =SUM(S19:S23) -> 27731 | T24: =Q24/R24 -> 1.6359203 | V24: =SUM(V19:V23) -> 40575
V25: =V24/R24 -> 1.583092
Q26: =25600*1.2 -> 30720

Sheet Perbandingan
B3: PT KRAKATAU BAJA KONSTRUKSI
B4: REKAP HILIRISASI 2023 sd 2024
B6: JENIS PRODUK | D6: Th 2022 | E6: Th 2023 | I6: Th 2024
C7: Entitas | D7: Tonase | E7: Tonase | F7: Revenue | G7: Gross Profit | I7: Tonase | J7: Revenue | K7: Gross Profit
B8: Steel Component | C8: 1. KBK | D8: 6868.9573 | E8: 3880.7409 | F8: 21.7318 | G8: 1.5401928 | I8: =SUMIF('Realisasi Hilirisasi'!$D:$D,Perbandingan!$B8,'Realisasi Hilirisasi'!E:E)-I9 -> 528.70598 | J8: =SUMIF('Realisasi Hilirisasi'!$D:$D,Perbandingan!$B8,'Realisasi Hilirisasi'!F:F)/1000000000-J9 -> 45.352707 | K8: =SUMIF('Realisasi Hilirisasi'!$D:$D,Perbandingan!$B8,'Realisasi Hilirisasi'!G:G)/1000000000-K9 -> 2.299841
B9: Heavy Section Terfabrikasi | C9: 1. KBK | E9: 0 | F9: 0 | G9: 0 | I9: 2868.6178
B10: Cut to Length | C10: 1. KBK | D10: 2259.6654 | E10: 3445.0193 | F10: 27.908813 | G10: 2.3858712 | I10: =SUMIF('Realisasi Hilirisasi'!$D:$D,Perbandingan!$B10,'Realisasi Hilirisasi'!E:E) -> 0 | J10: =SUMIF('Realisasi Hilirisasi'!$D:$D,Perbandingan!$B10,'Realisasi Hilirisasi'!F:F)/1000000000 -> 0 | K10: =SUMIF('Realisasi Hilirisasi'!$D:$D,Perbandingan!$B10,'Realisasi Hilirisasi'!G:G)/1000000000 -> 0 | N10: Tower
B11: Steel Structure | C11: 1. KBK | E11: 1931.4773 | F11: 42.288445 | G11: 3.0877236 | I11: =SUMIF('Realisasi Hilirisasi'!$D:$D,Perbandingan!$B11,'Realisasi Hilirisasi'!E:E) -> 1962.1941 | J11: =SUMIF('Realisasi Hilirisasi'!$D:$D,Perbandingan!$B11,'Realisasi Hilirisasi'!F:F)/1000000000 -> 59.722105 | K11: =SUMIF('Realisasi Hilirisasi'!$D:$D,Perbandingan!$B11,'Realisasi Hilirisasi'!G:G)/1000000000 -> 0.81948819 | N11: Steel Structure
